[2020-02-25 16:02:07,541] [WARNING] Not Found: /favicon.ico
[2020-02-25 17:19:12,838] [WARNING] Not Found: /favicon.ico
[2020-02-25 18:06:40,911] [WARNING] Not Found: /favicon.ico
[2020-02-26 14:32:04,611] [WARNING] Not Found: /favicon.ico
[2020-02-26 14:32:15,593] [INFO] 提交数据:20200225.txt
[2020-02-26 15:03:11,117] [WARNING] Not Found: /favicon.ico
[2020-02-26 15:03:19,291] [WARNING] Not Found: /favicon.ico
[2020-02-26 15:03:36,841] [WARNING] Not Found: /favicon.ico
[2020-02-26 15:04:11,926] [WARNING] Not Found: /favicon.ico
[2020-02-26 15:24:52,622] [INFO] 提交数据:20200225.txt
[2020-02-26 15:41:09,867] [WARNING] Not Found: /favicon.ico
[2020-02-26 15:41:17,678] [INFO] 提交数据:20200225.txt
[2020-02-26 15:42:15,264] [WARNING] Not Found: /favicon.ico
[2020-02-26 15:42:22,415] [INFO] 提交数据:20200225.txt
[2020-02-27 09:31:15,780] [WARNING] Not Found: /favicon.ico
[2020-02-27 10:56:06,412] [WARNING] Not Found: /favicon.ico
[2020-02-27 10:58:53,108] [INFO] 提交数据:测试数据二.txt
[2020-02-27 11:17:08,892] [INFO] 提交数据:测试数据一.txt
[2020-02-27 16:16:30,370] [ERROR] 文件名:20200226.txt, 错误信息:could not convert string to float: 'N/A'
[2020-02-27 16:16:30,788] [WARNING] Not Found: /
[2020-02-27 16:16:40,011] [ERROR] 文件名:20200226.txt, 错误信息:could not convert string to float: 'N/A'
[2020-02-27 16:16:40,043] [WARNING] Not Found: /
[2020-02-27 16:17:39,279] [ERROR] 文件名:20200226.txt, 错误信息:could not convert string to float: 'N/A'
[2020-02-27 16:17:39,325] [WARNING] Not Found: /
[2020-02-27 16:18:27,124] [WARNING] Not Found: /favicon.ico
[2020-02-27 16:19:04,440] [ERROR] 文件名:20200226.txt, 错误信息:could not convert string to float: 'N/A'
[2020-02-27 16:19:04,487] [WARNING] Not Found: /
[2020-02-27 16:20:24,416] [WARNING] Not Found: /favicon.ico
[2020-02-27 16:20:34,959] [INFO] 提交数据:20200226.txt
[2020-02-27 16:22:05,644] [ERROR] 文件名:20200226.txt, 错误信息:could not convert string to float: 'N/A'
[2020-02-27 16:22:05,675] [WARNING] Not Found: /
[2020-02-27 16:24:07,146] [WARNING] Not Found: /favicon.ico
[2020-02-27 16:24:33,347] [ERROR] 文件名:20200226.txt, 错误信息:could not convert string to float: 'N/A'
[2020-02-27 16:24:33,378] [WARNING] Not Found: /
[2020-02-27 16:25:15,557] [ERROR] 文件名:20200226.txt, 错误信息:could not convert string to float: 'N/A'
[2020-02-27 16:25:15,604] [WARNING] Not Found: /
[2020-02-27 16:25:37,477] [ERROR] 文件名:20200226.txt, 错误信息:could not convert string to float: 'N/A'
[2020-02-27 16:25:37,523] [WARNING] Not Found: /
[2020-02-27 16:25:49,013] [WARNING] Not Found: /favicon.ico
[2020-02-27 16:27:20,705] [ERROR] 文件名:20200226.txt, 错误信息:could not convert string to float: 'N/A'
[2020-02-27 16:27:20,752] [WARNING] Not Found: /
[2020-02-27 16:33:09,003] [WARNING] Not Found: /favicon.ico
[2020-02-27 16:33:15,465] [ERROR] 文件名:20200226.txt, 错误信息:could not convert string to float: 'N/A'
[2020-02-27 16:33:15,637] [WARNING] Not Found: /
[2020-02-27 16:34:08,498] [ERROR] 文件名:20200226.txt, 错误信息:could not convert string to float: 'N/A'
[2020-02-27 16:34:08,521] [WARNING] Not Found: /
[2020-02-27 16:35:56,249] [ERROR] 文件名:20200226.txt, 错误信息:could not convert string to float: 'N/A'
[2020-02-27 16:35:56,444] [WARNING] Not Found: /
[2020-02-27 16:36:14,932] [ERROR] Internal Server Error: /
Traceback (most recent call last):
  File "c:\users\lihua\appdata\local\programs\python\python37\lib\site-packages\django\core\handlers\exception.py", line 34, in inner
    response = get_response(request)
  File "c:\users\lihua\appdata\local\programs\python\python37\lib\site-packages\django\core\handlers\base.py", line 115, in _get_response
    response = self.process_exception_by_middleware(e, request)
  File "c:\users\lihua\appdata\local\programs\python\python37\lib\site-packages\django\core\handlers\base.py", line 113, in _get_response
    response = wrapped_callback(request, *callback_args, **callback_kwargs)
  File ".\QCtool\views.py", line 29, in file_upload
    raise e
  File ".\QCtool\views.py", line 27, in file_upload
    content = handle_uploaded_file(file, item, num, types)
  File ".\QCtool\handle.py", line 20, in handle_uploaded_file
    return uald.output()
  File ".\QCtool\UAld.py", line 106, in output
    output["ALD_isarea"] =self.get_isarea(dic[self.UAld])
  File ".\QCtool\main.py", line 284, in get_isarea
    is_list.append(float(sample[istd]))
ValueError: could not convert string to float: 'N/A'
[2020-02-27 16:40:05,306] [ERROR] Internal Server Error: /
Traceback (most recent call last):
  File "c:\users\lihua\appdata\local\programs\python\python37\lib\site-packages\django\core\handlers\exception.py", line 34, in inner
    response = get_response(request)
  File "c:\users\lihua\appdata\local\programs\python\python37\lib\site-packages\django\core\handlers\base.py", line 115, in _get_response
    response = self.process_exception_by_middleware(e, request)
  File "c:\users\lihua\appdata\local\programs\python\python37\lib\site-packages\django\core\handlers\base.py", line 113, in _get_response
    response = wrapped_callback(request, *callback_args, **callback_kwargs)
  File ".\QCtool\views.py", line 29, in file_upload
    raise e
  File ".\QCtool\views.py", line 27, in file_upload
    content = handle_uploaded_file(file, item, num, types)
  File ".\QCtool\handle.py", line 20, in handle_uploaded_file
    return uald.output()
  File ".\QCtool\UAld.py", line 106, in output
    output["ALD_isarea"] =self.get_isarea(dic[self.UAld])
  File ".\QCtool\main.py", line 284, in get_isarea
    is_list.append(float(sample[istd]))
ValueError: could not convert string to float: 'N/A'
[2020-02-27 16:41:04,415] [ERROR] Internal Server Error: /
Traceback (most recent call last):
  File "c:\users\lihua\appdata\local\programs\python\python37\lib\site-packages\django\core\handlers\exception.py", line 34, in inner
    response = get_response(request)
  File "c:\users\lihua\appdata\local\programs\python\python37\lib\site-packages\django\core\handlers\base.py", line 115, in _get_response
    response = self.process_exception_by_middleware(e, request)
  File "c:\users\lihua\appdata\local\programs\python\python37\lib\site-packages\django\core\handlers\base.py", line 113, in _get_response
    response = wrapped_callback(request, *callback_args, **callback_kwargs)
  File ".\QCtool\views.py", line 29, in file_upload
    raise e
  File ".\QCtool\views.py", line 27, in file_upload
    content = handle_uploaded_file(file, item, num, types)
  File ".\QCtool\handle.py", line 20, in handle_uploaded_file
    return uald.output()
  File ".\QCtool\UAld.py", line 106, in output
    output["ALD_isarea"] =self.get_isarea(dic[self.UAld])
  File ".\QCtool\main.py", line 284, in get_isarea
    is_list.append(float(sample[istd]))
ValueError: could not convert string to float: 'N/A'
[2020-02-27 16:43:01,611] [INFO] 提交数据:20200226.txt
[2020-02-27 16:43:34,960] [INFO] 提交数据:20200226.txt
[2020-02-27 16:43:39,662] [WARNING] Not Found: /favicon.ico
[2020-02-27 16:43:47,534] [INFO] 提交数据:20200226.txt
[2020-02-27 16:44:02,652] [INFO] 提交数据:20200226.txt
[2020-02-27 16:44:37,307] [INFO] 提交数据:20200226.txt
[2020-02-28 16:26:05,100] [WARNING] Not Found: /favicon.ico
[2020-02-28 16:26:14,631] [INFO] 提交数据:20200227.txt
[2020-02-28 18:22:31,388] [WARNING] Not Found: /favicon.ico
[2020-02-28 18:25:02,040] [INFO] 提交数据:UMNs-20200228.xml
[2020-02-28 18:25:05,019] [WARNING] Not Found: /favicon.ico
[2020-02-28 18:44:47,327] [WARNING] Not Found: /favicon.ico
[2020-02-28 18:44:51,726] [WARNING] Not Found: /favicon.ico
[2020-02-28 18:44:55,346] [WARNING] Not Found: /favicon.ico
[2020-02-28 18:44:57,233] [WARNING] Not Found: /favicon.ico
[2020-02-28 18:47:43,547] [WARNING] Not Found: /favicon.ico
[2020-02-28 18:48:20,863] [INFO] 提交数据:UMNs-20200228.xml
[2020-02-28 18:48:22,984] [WARNING] Not Found: /favicon.ico
[2020-02-29 08:42:22,731] [WARNING] Not Found: /favicon.ico
[2020-02-29 16:40:32,954] [WARNING] Not Found: /favicon.ico
[2020-02-29 16:40:40,270] [INFO] 提交数据:20200228.txt
[2020-02-29 16:52:53,974] [WARNING] Not Found: /favicon.ico
[2020-02-29 16:53:00,448] [INFO] 提交数据:20200228.txt
[2020-02-29 16:58:06,201] [WARNING] Not Found: /favicon.ico
[2020-02-29 16:58:12,332] [INFO] 提交数据:20200228.txt
[2020-02-29 17:10:02,397] [INFO] 提交数据:20200227.txt
[2020-02-29 17:54:28,123] [WARNING] Not Found: /favicon.ico
[2020-02-29 17:56:35,373] [INFO] 提交数据:UMNs-20200228-1.xml
[2020-03-01 09:06:19,380] [WARNING] Not Found: /favicon.ico
[2020-03-01 09:12:40,062] [INFO] 提交数据:UMNs-20200229.xml
[2020-03-01 10:11:17,461] [WARNING] Not Found: /favicon.ico
[2020-03-01 10:43:32,882] [WARNING] Not Found: /favicon.ico
[2020-03-01 10:44:54,378] [INFO] 提交数据:UMNs-20200228-1.xml
[2020-03-01 10:49:38,364] [WARNING] Not Found: /favicon.ico
[2020-03-01 10:49:51,687] [INFO] 提交数据:UMNs-20200229.xml
[2020-03-01 14:30:45,565] [WARNING] Not Found: /favicon.ico
[2020-03-01 18:14:15,953] [WARNING] Not Found: /favicon.ico
[2020-03-01 18:14:32,068] [INFO] 提交数据:20200229.txt
[2020-03-01 18:17:20,795] [INFO] 提交数据:20200229.txt
[2020-03-01 18:28:00,998] [WARNING] Not Found: /favicon.ico
[2020-03-01 18:30:56,649] [WARNING] Not Found: /favicon.ico
[2020-03-01 18:31:03,263] [INFO] 提交数据:20200227.txt
[2020-03-02 09:11:34,439] [WARNING] Not Found: /favicon.ico
[2020-03-02 09:11:41,023] [INFO] 提交数据:20200301.txt
[2020-03-02 10:24:42,876] [WARNING] Not Found: /favicon.ico
[2020-03-02 10:37:44,409] [INFO] 提交数据:测试数据二.txt
[2020-03-02 14:25:55,200] [WARNING] Not Found: /favicon.ico
[2020-03-02 14:26:12,002] [INFO] 提交数据:20200301.txt
[2020-03-02 16:19:48,880] [WARNING] Not Found: /favicon.ico
[2020-03-02 16:19:55,182] [INFO] 提交数据:20200301.txt
[2020-03-02 16:21:29,516] [INFO] 提交数据:20200301.txt
[2020-03-02 16:22:42,210] [INFO] 提交数据:20200301.txt
[2020-03-02 16:58:39,398] [WARNING] Not Found: /favicon.ico
[2020-03-02 16:59:12,318] [ERROR] Internal Server Error: /
Traceback (most recent call last):
  File "c:\users\lihua\appdata\local\programs\python\python37\lib\site-packages\django\core\handlers\exception.py", line 34, in inner
    response = get_response(request)
  File "c:\users\lihua\appdata\local\programs\python\python37\lib\site-packages\django\core\handlers\base.py", line 115, in _get_response
    response = self.process_exception_by_middleware(e, request)
  File "c:\users\lihua\appdata\local\programs\python\python37\lib\site-packages\django\core\handlers\base.py", line 113, in _get_response
    response = wrapped_callback(request, *callback_args, **callback_kwargs)
  File ".\QCtool\views.py", line 29, in file_upload
    raise e
  File ".\QCtool\views.py", line 27, in file_upload
    content = handle_uploaded_file(file, item, num, types)
  File ".\QCtool\handle.py", line 18, in handle_uploaded_file
    return uald.output()
  File ".\QCtool\UAld.py", line 89, in output
    raise IOError("无法识别原始数据格式")
OSError: 无法识别原始数据格式
[2020-03-02 16:59:30,838] [ERROR] Internal Server Error: /
Traceback (most recent call last):
  File "c:\users\lihua\appdata\local\programs\python\python37\lib\site-packages\django\core\handlers\exception.py", line 34, in inner
    response = get_response(request)
  File "c:\users\lihua\appdata\local\programs\python\python37\lib\site-packages\django\core\handlers\base.py", line 115, in _get_response
    response = self.process_exception_by_middleware(e, request)
  File "c:\users\lihua\appdata\local\programs\python\python37\lib\site-packages\django\core\handlers\base.py", line 113, in _get_response
    response = wrapped_callback(request, *callback_args, **callback_kwargs)
  File ".\QCtool\views.py", line 29, in file_upload
    raise e
  File ".\QCtool\views.py", line 27, in file_upload
    content = handle_uploaded_file(file, item, num, types)
  File ".\QCtool\handle.py", line 18, in handle_uploaded_file
    return uald.output()
  File ".\QCtool\UAld.py", line 89, in output
    raise IOError("无法识别原始数据格式")
OSError: 无法识别原始数据格式
[2020-03-02 17:00:40,702] [WARNING] Not Found: /favicon.ico
[2020-03-02 17:00:49,290] [INFO] 提交数据:UAld-20200302.txt
[2020-03-02 17:02:34,649] [WARNING] Not Found: /favicon.ico
[2020-03-02 17:02:43,555] [INFO] 提交数据:UAld-20200302.txt
[2020-03-03 10:44:51,450] [WARNING] Not Found: /favicon.ico
[2020-03-03 10:45:52,009] [INFO] 提交数据:UMNs-20200302.xml
[2020-03-03 11:40:29,773] [WARNING] Not Found: /favicon.ico
[2020-03-03 11:41:31,613] [ERROR] Internal Server Error: /
Traceback (most recent call last):
  File "c:\users\lihua\appdata\local\programs\python\python37\lib\site-packages\django\core\handlers\exception.py", line 34, in inner
    response = get_response(request)
  File "c:\users\lihua\appdata\local\programs\python\python37\lib\site-packages\django\core\handlers\base.py", line 115, in _get_response
    response = self.process_exception_by_middleware(e, request)
  File "c:\users\lihua\appdata\local\programs\python\python37\lib\site-packages\django\core\handlers\base.py", line 113, in _get_response
    response = wrapped_callback(request, *callback_args, **callback_kwargs)
  File ".\QCtool\views.py", line 29, in file_upload
    raise e
  File ".\QCtool\views.py", line 27, in file_upload
    content = handle_uploaded_file(file, item, num, types)
  File ".\QCtool\handle.py", line 12, in handle_uploaded_file
    return pmns.output()
  File ".\QCtool\PMNs.py", line 109, in output
    output["MN_r"] = self.get_r(dic[self.MN])
  File ".\QCtool\main.py", line 138, in get_r
    if R2 > 0.999:
UnboundLocalError: local variable 'R2' referenced before assignment
[2020-03-03 11:41:58,479] [INFO] 提交数据:20200122.xml
[2020-03-03 13:10:53,306] [WARNING] Not Found: /favicon.ico
[2020-03-03 16:02:34,408] [WARNING] Not Found: /favicon.ico
[2020-03-03 16:02:57,169] [INFO] 提交数据:20200120.xml
[2020-03-03 16:30:18,158] [WARNING] Not Found: /favicon.ico
[2020-03-03 16:30:32,657] [INFO] 提交数据:20200302.txt
[2020-03-03 16:52:13,438] [WARNING] Not Found: /favicon.ico
[2020-03-03 16:52:22,059] [INFO] 提交数据:测试数据二.txt
[2020-03-03 17:57:54,689] [WARNING] Not Found: /favicon.ico
[2020-03-03 17:57:56,894] [WARNING] Not Found: /favicon.ico
[2020-03-03 17:58:30,109] [WARNING] Not Found: /favicon.ico
[2020-03-03 17:58:35,461] [WARNING] Not Found: /favicon.ico
[2020-03-03 17:58:39,908] [WARNING] Not Found: /favicon.ico
[2020-03-03 17:59:04,742] [WARNING] Not Found: /favicon.ico
[2020-03-03 17:59:09,945] [WARNING] Not Found: /favicon.ico
[2020-03-03 17:59:13,902] [WARNING] Not Found: /favicon.ico
[2020-03-03 17:59:17,904] [WARNING] Not Found: /favicon.ico
[2020-03-03 17:59:58,276] [WARNING] Not Found: /favicon.ico
[2020-03-03 18:00:00,384] [WARNING] Not Found: /favicon.ico
[2020-03-03 18:00:30,534] [WARNING] Not Found: /favicon.ico
[2020-03-04 14:32:09,871] [WARNING] Not Found: /favicon.ico
[2020-03-04 16:14:37,678] [WARNING] Not Found: /favicon.ico
[2020-03-04 16:14:52,685] [INFO] 提交数据:20200303.txt
[2020-03-05 10:36:06,285] [WARNING] Not Found: /favicon.ico
[2020-03-05 10:36:08,495] [WARNING] Not Found: /favicon.ico
[2020-03-05 10:36:14,303] [WARNING] Not Found: /favicon.ico
[2020-03-05 10:36:17,184] [WARNING] Not Found: /favicon.ico
[2020-03-05 10:36:20,928] [WARNING] Not Found: /favicon.ico
[2020-03-05 10:38:22,650] [WARNING] Not Found: /favicon.ico
[2020-03-05 10:38:26,620] [WARNING] Not Found: /favicon.ico
[2020-03-05 10:38:40,535] [WARNING] Not Found: /favicon.ico
[2020-03-05 17:28:01,343] [WARNING] Not Found: /favicon.ico
[2020-03-05 17:28:13,449] [INFO] 提交数据:20200304.txt
[2020-03-05 17:33:43,371] [INFO] 提交数据:20200304.txt
[2020-03-05 18:31:49,065] [ERROR] Internal Server Error: /
Traceback (most recent call last):
  File "c:\users\lihua\appdata\local\programs\python\python37\lib\site-packages\django\core\handlers\exception.py", line 34, in inner
    response = get_response(request)
  File "c:\users\lihua\appdata\local\programs\python\python37\lib\site-packages\django\core\handlers\base.py", line 115, in _get_response
    response = self.process_exception_by_middleware(e, request)
  File "c:\users\lihua\appdata\local\programs\python\python37\lib\site-packages\django\core\handlers\base.py", line 113, in _get_response
    response = wrapped_callback(request, *callback_args, **callback_kwargs)
  File ".\QCtool\views.py", line 29, in file_upload
    raise e
  File ".\QCtool\views.py", line 27, in file_upload
    content = handle_uploaded_file(file, item, num, types)
  File ".\QCtool\handle.py", line 11, in handle_uploaded_file
    pmns = PMNs(f=f, instrument_num=instrument_num, instrument_type=instrument_type)
  File ".\QCtool\PMNs.py", line 34, in __init__
    super().__init__(self.NAME,
AttributeError: 'PMNs' object has no attribute 'NAME'
[2020-03-05 18:32:00,828] [WARNING] Not Found: /favicon.ico
[2020-03-05 18:32:11,951] [INFO] 提交数据:UMNs-20200305.xml
[2020-03-06 16:56:52,391] [WARNING] Not Found: /favicon.ico
[2020-03-06 16:56:59,951] [INFO] 提交数据:20200306.txt
[2020-03-06 17:19:47,796] [WARNING] Not Found: /favicon.ico
[2020-03-06 17:19:54,471] [INFO] 提交数据:20200305.txt
[2020-03-07 09:00:22,027] [WARNING] Not Found: /favicon.ico
[2020-03-07 17:41:35,680] [WARNING] Not Found: /favicon.ico
[2020-03-07 17:41:42,822] [INFO] 提交数据:20200306.txt
[2020-03-08 10:03:50,081] [WARNING] Not Found: /favicon.ico
[2020-03-08 10:03:52,546] [WARNING] Not Found: /favicon.ico
[2020-03-08 10:03:55,463] [WARNING] Not Found: /favicon.ico
[2020-03-08 10:03:58,318] [WARNING] Not Found: /favicon.ico
[2020-03-08 10:04:01,016] [WARNING] Not Found: /favicon.ico
[2020-03-08 10:04:06,960] [WARNING] Not Found: /favicon.ico
[2020-03-08 10:04:13,262] [WARNING] Not Found: /favicon.ico
[2020-03-08 10:04:17,038] [WARNING] Not Found: /favicon.ico
[2020-03-08 10:04:56,989] [WARNING] Not Found: /favicon.ico
[2020-03-08 10:04:59,033] [WARNING] Not Found: /favicon.ico
[2020-03-08 10:05:10,421] [WARNING] Not Found: /favicon.ico
[2020-03-08 10:05:12,371] [WARNING] Not Found: /favicon.ico
[2020-03-08 10:05:27,737] [WARNING] Not Found: /favicon.ico
[2020-03-08 10:05:30,311] [WARNING] Not Found: /favicon.ico
[2020-03-08 10:05:57,876] [WARNING] Not Found: /favicon.ico
[2020-03-08 10:05:59,545] [WARNING] Not Found: /favicon.ico
[2020-03-08 10:06:17,173] [WARNING] Not Found: /favicon.ico
[2020-03-08 10:06:19,357] [WARNING] Not Found: /favicon.ico
[2020-03-08 10:06:36,954] [WARNING] Not Found: /favicon.ico
[2020-03-08 10:06:46,922] [WARNING] Not Found: /favicon.ico
[2020-03-08 10:08:05,719] [WARNING] Not Found: /favicon.ico
[2020-03-08 10:08:08,605] [WARNING] Not Found: /favicon.ico
[2020-03-08 10:08:20,180] [WARNING] Not Found: /favicon.ico
[2020-03-08 10:08:21,631] [WARNING] Not Found: /favicon.ico
[2020-03-08 10:08:26,607] [WARNING] Not Found: /favicon.ico
[2020-03-08 10:08:29,883] [WARNING] Not Found: /favicon.ico
[2020-03-08 10:08:39,368] [WARNING] Not Found: /favicon.ico
[2020-03-08 10:08:50,430] [WARNING] Not Found: /favicon.ico
[2020-03-08 10:08:51,740] [WARNING] Not Found: /favicon.ico
[2020-03-08 10:08:54,486] [WARNING] Not Found: /favicon.ico
[2020-03-08 10:13:29,329] [WARNING] Not Found: /favicon.ico
[2020-03-08 10:13:39,220] [INFO] 提交数据:UAld-20200307.txt
[2020-03-08 14:55:40,666] [WARNING] Not Found: /favicon.ico
[2020-03-08 16:26:17,637] [WARNING] Not Found: /favicon.ico
[2020-03-08 16:26:24,507] [INFO] 提交数据:20200307.txt
[2020-03-08 16:29:59,643] [WARNING] Not Found: /favicon.ico
[2020-03-08 16:30:05,950] [INFO] 提交数据:20200307.txt
[2020-03-09 08:43:10,398] [WARNING] Not Found: /favicon.ico
[2020-03-09 08:43:14,626] [WARNING] Not Found: /favicon.ico
[2020-03-09 08:43:18,463] [WARNING] Not Found: /favicon.ico
[2020-03-09 08:43:23,284] [WARNING] Not Found: /favicon.ico
[2020-03-09 08:43:29,620] [WARNING] Not Found: /favicon.ico
[2020-03-09 13:42:22,043] [WARNING] Not Found: /favicon.ico
[2020-03-09 15:03:46,530] [WARNING] Not Found: /favicon.ico
[2020-03-09 15:04:00,117] [INFO] 提交数据:20200308.txt
[2020-03-09 16:15:47,107] [WARNING] Not Found: /favicon.ico
[2020-03-10 09:29:36,392] [WARNING] Not Found: /favicon.ico
[2020-03-10 11:37:49,400] [WARNING] Not Found: /favicon.ico
[2020-03-10 16:18:39,003] [WARNING] Not Found: /favicon.ico
[2020-03-10 16:18:51,394] [INFO] 提交数据:20200309.txt
[2020-03-10 16:58:29,349] [WARNING] Not Found: /favicon.ico
[2020-03-11 08:51:54,908] [WARNING] Not Found: /favicon.ico
[2020-03-11 10:22:56,572] [WARNING] Not Found: /favicon.ico
[2020-03-11 15:17:05,436] [WARNING] Not Found: /favicon.ico
[2020-03-11 15:17:18,219] [INFO] 提交数据:UMNs-20200224.xml
[2020-03-11 15:19:15,272] [INFO] 提交数据:UMNs-20200228.xml
[2020-03-11 15:24:42,922] [INFO] 提交数据:UMNs-20200222.xml
[2020-03-11 15:27:40,771] [WARNING] Not Found: /favicon.ico
[2020-03-11 15:28:03,560] [INFO] 提交数据:UMNs-20200217.xml
[2020-03-11 15:28:09,519] [INFO] 提交数据:UMNs-20200217.xml
[2020-03-11 15:28:13,109] [INFO] 提交数据:UMNs-20200217.xml
[2020-03-11 15:28:14,034] [INFO] 提交数据:UMNs-20200217.xml
[2020-03-11 15:29:14,325] [INFO] 提交数据:UMNs-20200222.xml
[2020-03-11 15:30:33,393] [INFO] 提交数据:UMNs-20200227.xml
[2020-03-11 15:31:37,514] [INFO] 提交数据:UMNs-20200307.xml
[2020-03-11 15:37:26,022] [WARNING] Not Found: /favicon.ico
[2020-03-11 15:45:15,917] [INFO] 提交数据:UMNs-20200106.xml
[2020-03-11 15:46:47,974] [INFO] 提交数据:UMNs-20200107.xml
[2020-03-11 15:47:35,655] [INFO] 提交数据:UMNs-20200212.xml
[2020-03-11 15:47:38,238] [INFO] 提交数据:UMNs-20200212.xml
[2020-03-11 17:41:26,432] [WARNING] Not Found: /favicon.ico
[2020-03-11 17:41:32,142] [INFO] 提交数据:20200310.txt
[2020-03-11 17:48:49,247] [WARNING] Not Found: /favicon.ico
[2020-03-11 17:48:54,894] [INFO] 提交数据:20200310.txt
[2020-03-12 09:12:23,609] [WARNING] Not Found: /favicon.ico
[2020-03-12 09:12:36,878] [INFO] 提交数据:20200311.txt
[2020-03-12 11:21:14,115] [WARNING] Not Found: /favicon.ico
[2020-03-12 17:56:28,981] [INFO] 提交数据:20200311.txt
[2020-03-13 17:14:13,447] [WARNING] Not Found: /favicon.ico
[2020-03-13 17:14:20,791] [INFO] 提交数据:20200312.txt
[2020-03-14 16:57:45,363] [WARNING] Not Found: /favicon.ico
[2020-03-14 16:57:53,481] [INFO] 提交数据:20200313.txt
[2020-03-14 16:59:27,828] [WARNING] Not Found: /favicon.ico
[2020-03-14 16:59:34,186] [INFO] 提交数据:20200313.txt
[2020-03-15 14:31:01,579] [WARNING] Not Found: /favicon.ico
[2020-03-15 15:50:18,119] [WARNING] Not Found: /favicon.ico
[2020-03-15 15:50:29,871] [INFO] 提交数据:UMNs-20200314.xml
[2020-03-15 17:00:04,696] [WARNING] Not Found: /favicon.ico
[2020-03-15 17:00:15,043] [INFO] 提交数据:20200314.txt
[2020-03-15 18:00:12,739] [WARNING] Not Found: /favicon.ico
[2020-03-15 18:00:14,734] [WARNING] Not Found: /favicon.ico
[2020-03-15 18:00:17,391] [WARNING] Not Found: /favicon.ico
[2020-03-15 18:00:19,484] [WARNING] Not Found: /favicon.ico
[2020-03-15 18:00:26,440] [WARNING] Not Found: /favicon.ico
[2020-03-15 18:01:05,713] [WARNING] Not Found: /favicon.ico
[2020-03-15 18:01:08,666] [WARNING] Not Found: /favicon.ico
[2020-03-15 18:01:20,264] [WARNING] Not Found: /favicon.ico
[2020-03-15 18:01:26,817] [WARNING] Not Found: /favicon.ico
[2020-03-15 18:01:33,505] [WARNING] Not Found: /favicon.ico
[2020-03-15 18:01:34,901] [WARNING] Not Found: /favicon.ico
[2020-03-15 18:01:42,996] [WARNING] Not Found: /favicon.ico
[2020-03-15 18:01:51,437] [WARNING] Not Found: /favicon.ico
[2020-03-15 18:02:00,679] [WARNING] Not Found: /favicon.ico
[2020-03-15 18:02:06,205] [WARNING] Not Found: /favicon.ico
[2020-03-15 18:02:15,220] [WARNING] Not Found: /favicon.ico
[2020-03-15 18:02:24,675] [WARNING] Not Found: /favicon.ico
[2020-03-16 09:28:13,049] [WARNING] Not Found: /favicon.ico
[2020-03-16 15:05:19,162] [WARNING] Not Found: /favicon.ico
[2020-03-16 16:06:00,164] [WARNING] Not Found: /favicon.ico
[2020-03-16 16:07:03,045] [WARNING] Not Found: /favicon.ico
[2020-03-16 16:08:02,066] [WARNING] Not Found: /favicon.ico
[2020-03-16 16:10:46,367] [WARNING] Not Found: /favicon.ico
[2020-03-16 16:33:03,255] [WARNING] Not Found: /favicon.ico
[2020-03-16 16:33:33,869] [WARNING] Not Found: /favicon.ico
[2020-03-16 17:36:09,290] [WARNING] Not Found: /favicon.ico
[2020-03-16 17:36:18,447] [INFO] 提交数据:20200315.txt
[2020-03-16 18:05:30,769] [WARNING] Not Found: /favicon.ico
[2020-03-16 18:05:44,046] [INFO] 提交数据:UMNs-20200315.xml
[2020-03-17 08:39:22,128] [INFO] 提交数据:20200316.txt
[2020-03-17 08:43:59,485] [WARNING] Not Found: /favicon.ico
[2020-03-17 16:54:36,782] [WARNING] Not Found: /favicon.ico
[2020-03-17 16:54:45,303] [INFO] 提交数据:20200316.txt
[2020-03-18 16:30:30,839] [WARNING] Not Found: /favicon.ico
[2020-03-18 16:30:45,831] [INFO] 提交数据:20200317.txt
[2020-03-19 17:46:26,697] [WARNING] Not Found: /favicon.ico
[2020-03-19 17:46:38,386] [INFO] 提交数据:20200318.txt
[2020-03-20 14:21:40,666] [WARNING] Not Found: /favicon.ico
[2020-03-20 14:51:07,581] [INFO] 提交数据:20200319.txt
[2020-03-20 14:52:23,188] [INFO] 提交数据:20200319.txt
[2020-03-20 14:52:50,117] [WARNING] Not Found: /favicon.ico
[2020-03-20 14:52:56,360] [WARNING] Not Found: /favicon.ico
[2020-03-20 14:53:22,159] [INFO] 提交数据:20200319.txt
[2020-03-20 14:54:10,901] [INFO] 提交数据:UMNs-20200319.xml
[2020-03-20 14:54:13,803] [WARNING] Not Found: /favicon.ico
[2020-03-20 14:54:16,035] [WARNING] Not Found: /favicon.ico
[2020-03-20 15:00:08,809] [WARNING] Not Found: /favicon.ico
[2020-03-20 15:01:08,668] [ERROR] Internal Server Error: /
Traceback (most recent call last):
  File "c:\users\lihua\appdata\local\programs\python\python37\lib\site-packages\django\core\handlers\exception.py", line 34, in inner
    response = get_response(request)
  File "c:\users\lihua\appdata\local\programs\python\python37\lib\site-packages\django\core\handlers\base.py", line 115, in _get_response
    response = self.process_exception_by_middleware(e, request)
  File "c:\users\lihua\appdata\local\programs\python\python37\lib\site-packages\django\core\handlers\base.py", line 113, in _get_response
    response = wrapped_callback(request, *callback_args, **callback_kwargs)
  File ".\QCtool\views.py", line 29, in file_upload
    raise e
  File ".\QCtool\views.py", line 27, in file_upload
    content = handle_uploaded_file(file, item, num, types)
  File ".\QCtool\handle.py", line 20, in handle_uploaded_file
    umns = UMNs(f=f, instrument_num=instrument_num, instrument_type=instrument_type)
  File ".\QCtool\UMNs.py", line 35, in __init__
    super().__init__(self.NAME,
AttributeError: 'UMNs' object has no attribute 'NAME'
[2020-03-20 15:01:18,013] [ERROR] Internal Server Error: /
Traceback (most recent call last):
  File "c:\users\lihua\appdata\local\programs\python\python37\lib\site-packages\django\core\handlers\exception.py", line 34, in inner
    response = get_response(request)
  File "c:\users\lihua\appdata\local\programs\python\python37\lib\site-packages\django\core\handlers\base.py", line 115, in _get_response
    response = self.process_exception_by_middleware(e, request)
  File "c:\users\lihua\appdata\local\programs\python\python37\lib\site-packages\django\core\handlers\base.py", line 113, in _get_response
    response = wrapped_callback(request, *callback_args, **callback_kwargs)
  File ".\QCtool\views.py", line 29, in file_upload
    raise e
  File ".\QCtool\views.py", line 27, in file_upload
    content = handle_uploaded_file(file, item, num, types)
  File ".\QCtool\handle.py", line 20, in handle_uploaded_file
    umns = UMNs(f=f, instrument_num=instrument_num, instrument_type=instrument_type)
  File ".\QCtool\UMNs.py", line 35, in __init__
    super().__init__(self.NAME,
AttributeError: 'UMNs' object has no attribute 'NAME'
[2020-03-20 15:01:24,333] [ERROR] Internal Server Error: /
Traceback (most recent call last):
  File "c:\users\lihua\appdata\local\programs\python\python37\lib\site-packages\django\core\handlers\exception.py", line 34, in inner
    response = get_response(request)
  File "c:\users\lihua\appdata\local\programs\python\python37\lib\site-packages\django\core\handlers\base.py", line 115, in _get_response
    response = self.process_exception_by_middleware(e, request)
  File "c:\users\lihua\appdata\local\programs\python\python37\lib\site-packages\django\core\handlers\base.py", line 113, in _get_response
    response = wrapped_callback(request, *callback_args, **callback_kwargs)
  File ".\QCtool\views.py", line 29, in file_upload
    raise e
  File ".\QCtool\views.py", line 27, in file_upload
    content = handle_uploaded_file(file, item, num, types)
  File ".\QCtool\handle.py", line 20, in handle_uploaded_file
    umns = UMNs(f=f, instrument_num=instrument_num, instrument_type=instrument_type)
  File ".\QCtool\UMNs.py", line 35, in __init__
    super().__init__(self.NAME,
AttributeError: 'UMNs' object has no attribute 'NAME'
[2020-03-20 15:01:31,055] [INFO] 提交数据:UMNs-20200319.xml
[2020-03-20 15:34:53,677] [WARNING] Not Found: /favicon.ico
[2020-03-20 15:36:26,398] [INFO] 提交数据:UMNs-20200319.xml
[2020-03-21 16:27:44,029] [WARNING] Not Found: /favicon.ico
[2020-03-21 16:28:03,810] [INFO] 提交数据:20200320.txt
[2020-03-21 17:22:12,448] [INFO] 提交数据:UMNs-20200321-1.xml
[2020-03-22 08:52:16,602] [WARNING] Not Found: /favicon.ico
[2020-03-22 10:07:37,522] [INFO] 提交数据:UMNs-20200321.xml
[2020-03-22 10:09:40,797] [WARNING] Not Found: /favicon.ico
[2020-03-22 10:09:45,648] [WARNING] Not Found: /favicon.ico
[2020-03-22 10:10:01,162] [WARNING] Not Found: /favicon.ico
[2020-03-22 10:10:20,964] [INFO] 提交数据:UMNs-20200321.xml
[2020-03-22 10:10:22,663] [WARNING] Not Found: /favicon.ico
[2020-03-22 10:11:25,700] [WARNING] Not Found: /favicon.ico
[2020-03-22 10:12:17,277] [INFO] 提交数据:UMNs-20200321.xml
[2020-03-22 10:12:18,884] [WARNING] Not Found: /favicon.ico
[2020-03-22 10:13:08,976] [WARNING] Not Found: /favicon.ico
[2020-03-22 10:13:27,057] [INFO] 提交数据:UMNs-20200321.xml
[2020-03-22 16:40:01,989] [WARNING] Not Found: /favicon.ico
[2020-03-23 17:26:43,203] [WARNING] Not Found: /favicon.ico
[2020-03-23 17:27:04,372] [INFO] 提交数据:20200322.txt
[2020-03-23 17:50:34,994] [WARNING] Not Found: /favicon.ico
[2020-03-23 17:51:07,836] [INFO] 提交数据:UMNs-20200323-1.xml
[2020-03-24 08:41:46,307] [WARNING] Not Found: /favicon.ico
[2020-03-24 10:43:55,246] [WARNING] Not Found: /favicon.ico
[2020-03-24 11:14:13,924] [WARNING] Not Found: /favicon.ico
[2020-03-24 11:14:47,932] [WARNING] Not Found: /favicon.ico
[2020-03-24 11:15:08,320] [ERROR] Internal Server Error: /
Traceback (most recent call last):
  File "c:\users\lihua\appdata\local\programs\python\python37\lib\site-packages\django\core\handlers\exception.py", line 34, in inner
    response = get_response(request)
  File "c:\users\lihua\appdata\local\programs\python\python37\lib\site-packages\django\core\handlers\base.py", line 115, in _get_response
    response = self.process_exception_by_middleware(e, request)
  File "c:\users\lihua\appdata\local\programs\python\python37\lib\site-packages\django\core\handlers\base.py", line 113, in _get_response
    response = wrapped_callback(request, *callback_args, **callback_kwargs)
  File ".\QCtool\views.py", line 29, in file_upload
    raise e
  File ".\QCtool\views.py", line 27, in file_upload
    content = handle_uploaded_file(file, item, num, types)
  File ".\QCtool\handle.py", line 20, in handle_uploaded_file
    umns = UMNs(f=f, instrument_num=instrument_num, instrument_type=instrument_type)
  File ".\QCtool\UMNs.py", line 35, in __init__
    super().__init__(self.NAME,
AttributeError: 'UMNs' object has no attribute 'NAME'
[2020-03-24 11:15:23,195] [INFO] 提交数据:UMNs-20200323.xml
[2020-03-24 11:20:48,912] [INFO] 提交数据:UMNs-20200323-2.xml
[2020-03-24 14:34:54,792] [WARNING] Not Found: /favicon.ico
[2020-03-24 15:36:30,133] [WARNING] Not Found: /favicon.ico
[2020-03-24 15:59:38,952] [WARNING] Not Found: /favicon.ico
[2020-03-24 17:32:41,175] [WARNING] Not Found: /favicon.ico
[2020-03-24 17:32:49,809] [INFO] 提交数据:20200323.txt
[2020-03-25 11:08:05,859] [WARNING] Not Found: /favicon.ico
[2020-03-25 14:19:33,696] [WARNING] Not Found: /favicon.ico
[2020-03-25 16:47:57,881] [INFO] 提交数据:20200324.txt
[2020-03-25 16:49:06,263] [WARNING] Not Found: /favicon.ico
[2020-03-25 16:49:12,499] [INFO] 提交数据:20200324.txt
[2020-03-26 08:49:31,820] [WARNING] Not Found: /favicon.ico
[2020-03-26 08:49:57,463] [INFO] 提交数据:UMNs-20200326.xml
[2020-03-26 11:57:43,270] [WARNING] Not Found: /favicon.ico
[2020-03-26 11:59:01,097] [WARNING] Not Found: /favicon.ico
[2020-03-26 17:48:13,944] [WARNING] Not Found: /favicon.ico
[2020-03-26 17:48:22,149] [INFO] 提交数据:20200325.txt
[2020-03-27 08:38:51,199] [WARNING] Not Found: /favicon.ico
[2020-03-27 09:17:32,986] [WARNING] Not Found: /favicon.ico
[2020-03-27 15:21:16,423] [WARNING] Not Found: /favicon.ico
[2020-03-27 15:21:16,471] [WARNING] Not Found: /favicon.ico
[2020-03-27 15:21:23,404] [INFO] 提交数据:20200326.txt
[2020-03-27 15:39:13,180] [WARNING] Not Found: /favicon.ico
[2020-03-28 12:06:58,538] [WARNING] Not Found: /favicon.ico
[2020-03-28 12:07:14,737] [INFO] 提交数据:20200328.txt
[2020-03-28 14:19:07,384] [WARNING] Not Found: /favicon.ico
[2020-03-28 14:19:09,338] [WARNING] Not Found: /favicon.ico
[2020-03-28 14:22:54,780] [INFO] 提交数据:UMNs-20200326.xml
[2020-03-28 14:22:59,732] [WARNING] Not Found: /favicon.ico
[2020-03-28 15:19:12,346] [WARNING] Not Found: /favicon.ico
[2020-03-28 15:19:41,106] [INFO] 提交数据:UMNs-20200326.xml
[2020-03-28 17:05:03,003] [WARNING] Not Found: /favicon.ico
[2020-03-28 17:05:10,867] [INFO] 提交数据:20200327.txt
[2020-03-28 17:05:12,700] [INFO] 提交数据:20200327.txt
[2020-03-29 10:26:10,778] [WARNING] Not Found: /favicon.ico
[2020-03-29 10:26:57,503] [INFO] 提交数据:YZ02.txt
[2020-03-29 10:36:36,062] [WARNING] Not Found: /favicon.ico
[2020-03-29 10:36:44,939] [INFO] 提交数据:YZ02.txt
[2020-03-29 10:36:59,173] [ERROR] 文件名:YZ03.txt, 错误信息:local variable 'std0_area' referenced before assignment
[2020-03-29 10:36:59,397] [WARNING] Not Found: /
[2020-03-29 10:37:05,280] [ERROR] 文件名:YZ03.txt, 错误信息:local variable 'std0_area' referenced before assignment
[2020-03-29 10:37:05,322] [WARNING] Not Found: /
[2020-03-29 10:37:09,688] [INFO] 提交数据:YZ04.txt
[2020-03-29 10:37:28,185] [ERROR] 文件名:YZ03.txt, 错误信息:local variable 'std0_area' referenced before assignment
[2020-03-29 10:37:28,218] [WARNING] Not Found: /
[2020-03-29 10:39:58,998] [INFO] 提交数据:YZ18.txt
[2020-03-29 10:40:37,323] [ERROR] 文件名:YZ23.txt, 错误信息:mean requires at least one data point
[2020-03-29 10:40:37,356] [WARNING] Not Found: /
[2020-03-29 10:40:58,084] [INFO] 提交数据:YZ06-20200317.csv
[2020-03-29 10:48:47,309] [WARNING] Not Found: /favicon.ico
[2020-03-29 14:07:49,704] [WARNING] Not Found: /favicon.ico
[2020-03-29 14:08:14,921] [INFO] 提交数据:YZ18.txt
[2020-03-29 14:08:44,742] [INFO] 提交数据:YZ18.txt
[2020-03-29 14:13:32,565] [INFO] 提交数据:YZ18.txt
[2020-03-29 17:25:37,595] [WARNING] Not Found: /favicon.ico
[2020-03-29 17:25:47,532] [INFO] 提交数据:20200328.txt
[2020-03-29 17:29:59,447] [WARNING] Not Found: /favicon.ico
[2020-03-29 17:40:10,783] [INFO] 提交数据:YZ18.txt
[2020-03-29 17:40:46,481] [INFO] 提交数据:20191212.txt
[2020-03-29 17:44:30,916] [INFO] 提交数据:YZ02-20191018.txt
[2020-03-30 09:03:26,597] [WARNING] Not Found: /favicon.ico
[2020-03-30 10:23:34,540] [WARNING] Not Found: /favicon.ico
[2020-03-30 10:24:10,012] [WARNING] Not Found: /favicon.ico
[2020-03-30 10:24:19,034] [INFO] 提交数据:数据导出-YZ18.docx
[2020-03-30 10:37:28,713] [WARNING] Not Found: /favicon.ico
[2020-03-30 10:37:51,676] [INFO] 提交数据:数据导出-YZ02.docx
[2020-03-30 10:40:50,010] [WARNING] Not Found: /favicon.ico
[2020-03-30 10:41:14,906] [ERROR] 文件名:UMNs-20200329-1.xml, 错误信息:__init__() takes 13 positional arguments but 14 were given
[2020-03-30 10:41:14,952] [WARNING] Not Found: /
[2020-03-30 10:41:46,628] [ERROR] 文件名:UMNs-20200329-1.xml, 错误信息:__init__() takes 13 positional arguments but 14 were given
[2020-03-30 10:41:46,672] [WARNING] Not Found: /
[2020-03-30 10:42:17,981] [WARNING] Not Found: /favicon.ico
[2020-03-30 10:42:32,216] [ERROR] 文件名:UMNs-20200323-2.xml, 错误信息:__init__() takes 13 positional arguments but 14 were given
[2020-03-30 10:42:32,232] [WARNING] Not Found: /
[2020-03-30 10:42:53,095] [ERROR] 文件名:UMNs-20200326.xml, 错误信息:__init__() takes 13 positional arguments but 14 were given
[2020-03-30 10:42:53,111] [WARNING] Not Found: /
[2020-03-30 10:43:07,505] [WARNING] Not Found: /favicon.ico
[2020-03-30 10:43:37,423] [ERROR] 文件名:UMNs-20200329-1.xml, 错误信息:__init__() takes 13 positional arguments but 14 were given
[2020-03-30 10:43:37,454] [WARNING] Not Found: /
[2020-03-30 10:45:14,096] [WARNING] Not Found: /favicon.ico
[2020-03-30 10:46:22,188] [ERROR] 文件名:UMNs-20200329-1.xml, 错误信息:__init__() takes 13 positional arguments but 14 were given
[2020-03-30 10:46:22,204] [WARNING] Not Found: /
[2020-03-30 10:47:12,330] [INFO] 提交数据:UMNs-20200329-1.xml
[2020-03-30 10:47:27,574] [INFO] 提交数据:UMNs-20200329-1.xml
[2020-03-30 10:47:28,972] [INFO] 提交数据:UMNs-20200329-1.xml
[2020-03-30 15:58:28,942] [WARNING] Not Found: /favicon.ico
[2020-03-30 16:05:57,364] [WARNING] Not Found: /favicon.ico
[2020-03-30 16:52:22,938] [INFO] 提交数据:20200329.txt
[2020-03-31 08:32:02,424] [WARNING] Not Found: /favicon.ico
[2020-03-31 08:32:16,260] [ERROR] 文件名:数据导出-YZ18.docx, 错误信息:could not convert string to float: 
[2020-03-31 08:32:16,358] [WARNING] Not Found: /
[2020-03-31 08:32:22,457] [ERROR] 文件名:数据导出-YZ18.docx, 错误信息:could not convert string to float: 
[2020-03-31 08:32:22,479] [WARNING] Not Found: /
[2020-03-31 08:32:28,604] [ERROR] 文件名:YZ05.txt, 错误信息:local variable 'std0_area' referenced before assignment
[2020-03-31 08:32:28,651] [WARNING] Not Found: /
[2020-03-31 08:33:08,248] [ERROR] 文件名:YZ05.txt, 错误信息:local variable 'std0_area' referenced before assignment
[2020-03-31 08:33:08,358] [WARNING] Not Found: /
[2020-03-31 08:33:52,514] [ERROR] 文件名:数据导出-YZ18.docx, 错误信息:could not convert string to float: 
[2020-03-31 08:33:52,538] [WARNING] Not Found: /
[2020-03-31 08:34:18,656] [INFO] 提交数据:YZ06-20200317.csv
[2020-03-31 08:34:29,969] [ERROR] 文件名:数据导出-YZ18.docx, 错误信息:could not convert string to float: 
[2020-03-31 08:34:29,993] [WARNING] Not Found: /
[2020-03-31 08:35:17,289] [INFO] 提交数据:数据导出-YZ18.docx
[2020-03-31 08:35:53,411] [WARNING] Not Found: /favicon.ico
[2020-03-31 08:36:11,245] [INFO] 提交数据:数据导出-YZ18.docx
[2020-03-31 08:40:29,333] [WARNING] Not Found: /favicon.ico
[2020-03-31 08:45:15,547] [INFO] 提交数据:数据导出-YZ18.docx
[2020-03-31 08:48:29,877] [WARNING] Not Found: /favicon.ico
[2020-03-31 08:48:42,638] [WARNING] Not Found: /favicon.ico
[2020-03-31 08:48:56,069] [WARNING] Not Found: /favicon.ico
[2020-03-31 08:48:58,331] [WARNING] Not Found: /favicon.ico
[2020-03-31 08:49:00,250] [WARNING] Not Found: /favicon.ico
[2020-03-31 08:49:09,268] [WARNING] Not Found: /favicon.ico
[2020-03-31 08:49:13,388] [WARNING] Not Found: /favicon.ico
[2020-03-31 08:49:15,603] [WARNING] Not Found: /favicon.ico
[2020-03-31 08:49:17,912] [WARNING] Not Found: /favicon.ico
[2020-03-31 08:49:20,858] [WARNING] Not Found: /favicon.ico
[2020-03-31 08:49:24,577] [WARNING] Not Found: /favicon.ico
[2020-03-31 08:49:27,722] [WARNING] Not Found: /favicon.ico
[2020-03-31 08:49:34,224] [WARNING] Not Found: /favicon.ico
[2020-03-31 08:49:42,117] [WARNING] Not Found: /favicon.ico
[2020-03-31 08:50:23,535] [INFO] 提交数据:数据导出-YZ18.docx
[2020-03-31 08:54:06,506] [WARNING] Not Found: /favicon.ico
[2020-03-31 09:00:01,394] [WARNING] Not Found: /favicon.ico
[2020-03-31 10:14:33,169] [INFO] Watching for file changes with StatReloader
[2020-03-31 10:14:47,234] [INFO] "GET / HTTP/1.1" 200 3290
[2020-03-31 10:14:47,323] [INFO] "GET /static/style.css HTTP/1.1" 200 1342
[2020-03-31 10:14:47,362] [INFO] "GET /static/script.js HTTP/1.1" 200 1169
[2020-03-31 10:14:47,362] [INFO] "GET /static/table2CSV.js HTTP/1.1" 200 1552
[2020-03-31 10:14:47,450] [INFO] "GET /static/echarts.min.js HTTP/1.1" 200 759712
[2020-03-31 10:14:47,561] [WARNING] Not Found: /favicon.ico
[2020-03-31 10:14:47,561] [WARNING] "GET /favicon.ico HTTP/1.1" 404 2323
[2020-03-31 10:14:58,735] [INFO] "GET /admin HTTP/1.1" 301 0
[2020-03-31 10:14:58,747] [INFO] "GET /admin/ HTTP/1.1" 302 0
[2020-03-31 10:14:58,935] [INFO] "GET /admin/login/?next=/admin/ HTTP/1.1" 200 1816
[2020-03-31 10:14:58,945] [INFO] "GET /static/admin/css/base.css HTTP/1.1" 200 16378
[2020-03-31 10:14:58,966] [INFO] "GET /static/admin/css/login.css HTTP/1.1" 200 1233
[2020-03-31 10:14:58,966] [INFO] "GET /static/admin/css/responsive.css HTTP/1.1" 200 17944
[2020-03-31 10:14:58,968] [INFO] "GET /static/admin/css/fonts.css HTTP/1.1" 200 423
[2020-03-31 10:14:58,989] [INFO] "GET /static/admin/fonts/Roboto-Regular-webfont.woff HTTP/1.1" 200 85876
[2020-03-31 10:14:58,990] [INFO] "GET /static/admin/fonts/Roboto-Light-webfont.woff HTTP/1.1" 200 85692
[2020-03-31 10:15:03,659] [INFO] "POST /admin/login/?next=/admin/ HTTP/1.1" 302 0
[2020-03-31 10:15:03,690] [INFO] "GET /admin/ HTTP/1.1" 200 7733
[2020-03-31 10:15:03,702] [INFO] "GET /static/admin/css/dashboard.css HTTP/1.1" 200 412
[2020-03-31 10:15:03,709] [INFO] "GET /static/admin/img/icon-addlink.svg HTTP/1.1" 200 331
[2020-03-31 10:15:03,709] [INFO] "GET /static/admin/img/icon-changelink.svg HTTP/1.1" 200 380
[2020-03-31 10:15:03,779] [INFO] "GET /static/admin/fonts/Roboto-Bold-webfont.woff HTTP/1.1" 200 86184
[2020-03-31 10:15:06,739] [INFO] "GET /admin/QCtool/ionratioframe/ HTTP/1.1" 200 3569
[2020-03-31 10:15:06,749] [INFO] "GET /static/admin/css/changelists.css HTTP/1.1" 200 6170
[2020-03-31 10:15:06,761] [INFO] "GET /admin/jsi18n/ HTTP/1.1" 200 7722
[2020-03-31 10:15:06,762] [INFO] "GET /static/admin/js/core.js HTTP/1.1" 200 7099
[2020-03-31 10:15:06,764] [INFO] "GET /static/admin/js/actions.js HTTP/1.1" 200 6766
[2020-03-31 10:15:06,764] [INFO] "GET /static/admin/js/jquery.init.js HTTP/1.1" 200 363
[2020-03-31 10:15:06,766] [INFO] "GET /static/admin/js/admin/RelatedObjectLookups.js HTTP/1.1" 200 6918
[2020-03-31 10:15:06,774] [INFO] "GET /static/admin/js/prepopulate.js HTTP/1.1" 200 1530
[2020-03-31 10:15:06,775] [INFO] "GET /static/admin/js/urlify.js HTTP/1.1" 200 8941
[2020-03-31 10:15:06,788] [INFO] "GET /static/admin/js/vendor/xregexp/xregexp.js HTTP/1.1" 200 128820
[2020-03-31 10:15:06,789] [INFO] "GET /static/admin/js/vendor/jquery/jquery.js HTTP/1.1" 200 271817
[2020-03-31 10:15:06,823] [INFO] "GET /static/admin/img/tooltag-add.svg HTTP/1.1" 200 331
[2020-03-31 10:15:08,358] [INFO] "GET /admin/QCtool/ionratioframe/add/ HTTP/1.1" 200 5023
[2020-03-31 10:15:08,378] [INFO] "GET /admin/jsi18n/ HTTP/1.1" 200 7722
[2020-03-31 10:15:08,379] [INFO] "GET /static/admin/css/forms.css HTTP/1.1" 200 8518
[2020-03-31 10:15:08,379] [INFO] "GET /static/admin/js/prepopulate_init.js HTTP/1.1" 200 495
[2020-03-31 10:15:08,403] [INFO] "GET /static/admin/js/change_form.js HTTP/1.1" 200 712
[2020-03-31 10:15:08,406] [INFO] "GET /static/admin/css/widgets.css HTTP/1.1" 200 10340
[2020-03-31 10:15:20,370] [INFO] "POST /admin/QCtool/ionratioframe/add/ HTTP/1.1" 302 0
[2020-03-31 10:15:20,461] [INFO] "GET /admin/QCtool/ionratioframe/ HTTP/1.1" 200 5487
[2020-03-31 10:15:20,478] [INFO] "GET /admin/jsi18n/ HTTP/1.1" 200 7722
[2020-03-31 10:15:20,499] [INFO] "GET /static/admin/img/icon-yes.svg HTTP/1.1" 200 436
[2020-03-31 10:15:22,332] [INFO] "GET /admin/QCtool/ionratioframe/add/ HTTP/1.1" 200 5023
[2020-03-31 10:15:22,349] [INFO] "GET /admin/jsi18n/ HTTP/1.1" 200 7722
[2020-03-31 10:15:31,735] [INFO] "POST /admin/QCtool/ionratioframe/add/ HTTP/1.1" 302 0
[2020-03-31 10:15:31,786] [INFO] "GET /admin/QCtool/ionratioframe/ HTTP/1.1" 200 5848
[2020-03-31 10:15:31,800] [INFO] "GET /admin/jsi18n/ HTTP/1.1" 200 7722
[2020-03-31 10:15:38,797] [INFO] "GET /admin/QCtool/ HTTP/1.1" 200 3372
[2020-03-31 10:15:45,582] [INFO] "GET /admin/QCtool/bigdataframe/ HTTP/1.1" 200 9152
[2020-03-31 10:15:45,599] [INFO] "GET /admin/jsi18n/ HTTP/1.1" 200 7722
[2020-03-31 10:15:53,647] [INFO] "GET /admin/QCtool/ HTTP/1.1" 200 3372
[2020-03-31 10:15:56,700] [INFO] "GET / HTTP/1.1" 200 3290
[2020-03-31 10:16:54,471] [INFO] E:\Data Processing Evaluation Tool\mysite\QCtool\Item\VD.py changed, reloading.
[2020-03-31 10:16:55,374] [INFO] Watching for file changes with StatReloader
[2020-03-31 10:17:10,281] [INFO] E:\Data Processing Evaluation Tool\mysite\QCtool\Item\VD.py changed, reloading.
[2020-03-31 10:17:11,170] [INFO] Watching for file changes with StatReloader
[2020-03-31 10:17:16,046] [INFO] E:\Data Processing Evaluation Tool\mysite\QCtool\Item\VD.py changed, reloading.
[2020-03-31 10:17:16,952] [INFO] Watching for file changes with StatReloader
[2020-03-31 10:17:24,154] [INFO] E:\Data Processing Evaluation Tool\mysite\QCtool\Item\VD.py changed, reloading.
[2020-03-31 10:17:25,022] [INFO] Watching for file changes with StatReloader
[2020-03-31 10:18:24,870] [INFO] E:\Data Processing Evaluation Tool\mysite\QCtool\main.py changed, reloading.
[2020-03-31 10:18:25,729] [INFO] Watching for file changes with StatReloader
[2020-03-31 10:18:38,499] [INFO] E:\Data Processing Evaluation Tool\mysite\QCtool\main.py changed, reloading.
[2020-03-31 10:18:39,379] [INFO] Watching for file changes with StatReloader
[2020-03-31 10:18:52,127] [INFO] E:\Data Processing Evaluation Tool\mysite\QCtool\main.py changed, reloading.
[2020-03-31 10:18:52,958] [INFO] Watching for file changes with StatReloader
[2020-03-31 10:18:56,573] [INFO] E:\Data Processing Evaluation Tool\mysite\QCtool\main.py changed, reloading.
[2020-03-31 10:18:57,425] [INFO] Watching for file changes with StatReloader
[2020-03-31 10:19:19,433] [INFO] E:\Data Processing Evaluation Tool\mysite\QCtool\main.py changed, reloading.
[2020-03-31 10:19:20,257] [INFO] Watching for file changes with StatReloader
[2020-03-31 10:19:54,308] [ERROR] 文件名:YZ06-20200317.csv, 错误信息:__init__() missing 1 required positional argument: 'LOCATE'
[2020-03-31 10:19:54,506] [WARNING] Not Found: /
[2020-03-31 10:19:54,506] [WARNING] "POST / HTTP/1.1" 404 1857
[2020-03-31 10:20:02,222] [INFO] E:\Data Processing Evaluation Tool\mysite\QCtool\main.py changed, reloading.
[2020-03-31 10:20:03,126] [INFO] Watching for file changes with StatReloader
[2020-03-31 10:20:03,502] [ERROR] 文件名:YZ06-20200317.csv, 错误信息:__init__() missing 1 required positional argument: 'LOCATE'
[2020-03-31 10:20:03,717] [WARNING] Not Found: /
[2020-03-31 10:20:03,718] [WARNING] "POST / HTTP/1.1" 404 1857
[2020-03-31 10:20:06,929] [ERROR] 文件名:YZ06-20200317.csv, 错误信息:__init__() missing 1 required positional argument: 'LOCATE'
[2020-03-31 10:20:06,950] [WARNING] Not Found: /
[2020-03-31 10:20:06,950] [WARNING] "POST / HTTP/1.1" 404 1857
[2020-03-31 10:20:22,225] [INFO] E:\Data Processing Evaluation Tool\mysite\QCtool\main.py changed, reloading.
[2020-03-31 10:20:23,127] [INFO] Watching for file changes with StatReloader
[2020-03-31 10:20:24,858] [ERROR] 文件名:YZ06-20200317.csv, 错误信息:__init__() missing 1 required positional argument: 'LOCATE'
[2020-03-31 10:20:25,079] [WARNING] Not Found: /
[2020-03-31 10:20:25,080] [WARNING] "POST / HTTP/1.1" 404 1857
[2020-03-31 10:20:36,061] [INFO] E:\Data Processing Evaluation Tool\mysite\QCtool\main.py changed, reloading.
[2020-03-31 10:20:36,962] [INFO] Watching for file changes with StatReloader
[2020-03-31 10:20:37,359] [ERROR] 文件名:YZ06-20200317.csv, 错误信息:name 'last_record' is not defined
[2020-03-31 10:20:37,580] [WARNING] Not Found: /
[2020-03-31 10:20:37,581] [WARNING] "POST / HTTP/1.1" 404 1831
[2020-03-31 10:20:40,453] [ERROR] 文件名:YZ06-20200317.csv, 错误信息:name 'last_record' is not defined
[2020-03-31 10:20:40,483] [WARNING] Not Found: /
[2020-03-31 10:20:40,483] [WARNING] "POST / HTTP/1.1" 404 1831
[2020-03-31 10:21:32,509] [INFO] E:\Data Processing Evaluation Tool\mysite\QCtool\main.py changed, reloading.
[2020-03-31 10:21:33,396] [INFO] Watching for file changes with StatReloader
[2020-03-31 10:21:34,518] [INFO] 提交数据:YZ06-20200317.csv
[2020-03-31 10:21:34,624] [INFO] "POST / HTTP/1.1" 200 33328
[2020-03-31 10:22:00,667] [INFO] E:\Data Processing Evaluation Tool\mysite\QCtool\main.py changed, reloading.
[2020-03-31 10:22:01,578] [INFO] Watching for file changes with StatReloader
[2020-03-31 10:22:44,393] [INFO] E:\Data Processing Evaluation Tool\mysite\QCtool\Item\VD.py changed, reloading.
[2020-03-31 10:22:45,479] [INFO] Watching for file changes with StatReloader
[2020-03-31 10:22:59,442] [INFO] E:\Data Processing Evaluation Tool\mysite\QCtool\Item\VD.py changed, reloading.
[2020-03-31 10:23:00,275] [INFO] Watching for file changes with StatReloader
[2020-03-31 10:24:11,740] [INFO] E:\Data Processing Evaluation Tool\mysite\QCtool\Item\VD.py changed, reloading.
[2020-03-31 10:24:12,678] [INFO] Watching for file changes with StatReloader
[2020-03-31 10:24:14,258] [ERROR] 文件名:YZ06-20200317.csv, 错误信息:__init__() missing 1 required positional argument: 'LOCATE'
[2020-03-31 10:24:14,460] [WARNING] Not Found: /
[2020-03-31 10:24:14,461] [WARNING] "POST / HTTP/1.1" 404 1857
[2020-03-31 10:24:39,325] [INFO] E:\Data Processing Evaluation Tool\mysite\QCtool\Item\VD.py changed, reloading.
[2020-03-31 10:24:40,679] [INFO] Watching for file changes with StatReloader
[2020-03-31 10:24:42,061] [INFO] 提交数据:YZ06-20200317.csv
[2020-03-31 10:24:42,119] [INFO] "POST / HTTP/1.1" 200 33328
[2020-03-31 10:25:35,425] [INFO] E:\Data Processing Evaluation Tool\mysite\QCtool\Item\VD.py changed, reloading.
[2020-03-31 10:25:36,314] [INFO] Watching for file changes with StatReloader
[2020-03-31 10:25:45,229] [INFO] E:\Data Processing Evaluation Tool\mysite\QCtool\views.py changed, reloading.
[2020-03-31 10:25:46,111] [INFO] Watching for file changes with StatReloader
[2020-03-31 10:25:46,852] [ERROR] Internal Server Error: /
Traceback (most recent call last):
  File "C:\Users\lihua\AppData\Local\Programs\Python\Python37\lib\site-packages\django\core\handlers\exception.py", line 34, in inner
    response = get_response(request)
  File "C:\Users\lihua\AppData\Local\Programs\Python\Python37\lib\site-packages\django\core\handlers\base.py", line 115, in _get_response
    response = self.process_exception_by_middleware(e, request)
  File "C:\Users\lihua\AppData\Local\Programs\Python\Python37\lib\site-packages\django\core\handlers\base.py", line 113, in _get_response
    response = wrapped_callback(request, *callback_args, **callback_kwargs)
  File "E:\Data Processing Evaluation Tool\mysite\QCtool\views.py", line 29, in file_upload
    raise e
  File "E:\Data Processing Evaluation Tool\mysite\QCtool\views.py", line 27, in file_upload
    content = handle_uploaded_file(file, item, num, types)
  File "E:\Data Processing Evaluation Tool\mysite\QCtool\Item\handle.py", line 23, in handle_uploaded_file
    return vd.output()
  File "E:\Data Processing Evaluation Tool\mysite\QCtool\Item\VD.py", line 493, in output
    dic = self.get_dic_data()
  File "E:\Data Processing Evaluation Tool\mysite\QCtool\Item\VD.py", line 262, in get_dic_data
    dic = self.Agilent_data_format()
  File "E:\Data Processing Evaluation Tool\mysite\QCtool\Item\VD.py", line 135, in Agilent_data_format
    raise
RuntimeError: No active exception to reraise
[2020-03-31 10:25:46,918] [ERROR] "POST / HTTP/1.1" 500 95160
[2020-03-31 10:27:41,436] [INFO] E:\Data Processing Evaluation Tool\mysite\QCtool\Item\VD.py changed, reloading.
[2020-03-31 10:27:42,323] [INFO] Watching for file changes with StatReloader
[2020-03-31 10:27:42,956] [ERROR] Internal Server Error: /
Traceback (most recent call last):
  File "C:\Users\lihua\AppData\Local\Programs\Python\Python37\lib\site-packages\django\core\handlers\exception.py", line 34, in inner
    response = get_response(request)
  File "C:\Users\lihua\AppData\Local\Programs\Python\Python37\lib\site-packages\django\core\handlers\base.py", line 115, in _get_response
    response = self.process_exception_by_middleware(e, request)
  File "C:\Users\lihua\AppData\Local\Programs\Python\Python37\lib\site-packages\django\core\handlers\base.py", line 113, in _get_response
    response = wrapped_callback(request, *callback_args, **callback_kwargs)
  File "E:\Data Processing Evaluation Tool\mysite\QCtool\views.py", line 29, in file_upload
    raise e
  File "E:\Data Processing Evaluation Tool\mysite\QCtool\views.py", line 27, in file_upload
    content = handle_uploaded_file(file, item, num, types)
  File "E:\Data Processing Evaluation Tool\mysite\QCtool\Item\handle.py", line 23, in handle_uploaded_file
    return vd.output()
  File "E:\Data Processing Evaluation Tool\mysite\QCtool\Item\VD.py", line 493, in output
    dic = self.get_dic_data()
  File "E:\Data Processing Evaluation Tool\mysite\QCtool\Item\VD.py", line 262, in get_dic_data
    dic = self.Agilent_data_format()
  File "E:\Data Processing Evaluation Tool\mysite\QCtool\Item\VD.py", line 162, in Agilent_data_format
    raise
RuntimeError: No active exception to reraise
[2020-03-31 10:27:43,022] [ERROR] "POST / HTTP/1.1" 500 97491
[2020-03-31 10:28:33,864] [INFO] E:\Data Processing Evaluation Tool\mysite\QCtool\Item\VD.py changed, reloading.
[2020-03-31 10:28:34,756] [INFO] Watching for file changes with StatReloader
[2020-03-31 10:28:35,434] [ERROR] Internal Server Error: /
Traceback (most recent call last):
  File "C:\Users\lihua\AppData\Local\Programs\Python\Python37\lib\site-packages\django\core\handlers\exception.py", line 34, in inner
    response = get_response(request)
  File "C:\Users\lihua\AppData\Local\Programs\Python\Python37\lib\site-packages\django\core\handlers\base.py", line 115, in _get_response
    response = self.process_exception_by_middleware(e, request)
  File "C:\Users\lihua\AppData\Local\Programs\Python\Python37\lib\site-packages\django\core\handlers\base.py", line 113, in _get_response
    response = wrapped_callback(request, *callback_args, **callback_kwargs)
  File "E:\Data Processing Evaluation Tool\mysite\QCtool\views.py", line 29, in file_upload
    raise e
  File "E:\Data Processing Evaluation Tool\mysite\QCtool\views.py", line 27, in file_upload
    content = handle_uploaded_file(file, item, num, types)
  File "E:\Data Processing Evaluation Tool\mysite\QCtool\Item\handle.py", line 23, in handle_uploaded_file
    return vd.output()
  File "E:\Data Processing Evaluation Tool\mysite\QCtool\Item\VD.py", line 493, in output
    dic = self.get_dic_data()
  File "E:\Data Processing Evaluation Tool\mysite\QCtool\Item\VD.py", line 262, in get_dic_data
    dic = self.Agilent_data_format()
  File "E:\Data Processing Evaluation Tool\mysite\QCtool\Item\VD.py", line 178, in Agilent_data_format
    raise
RuntimeError: No active exception to reraise
[2020-03-31 10:28:35,538] [ERROR] "POST / HTTP/1.1" 500 121823
[2020-03-31 10:29:43,895] [INFO] E:\Data Processing Evaluation Tool\mysite\QCtool\Item\VD.py changed, reloading.
[2020-03-31 10:29:44,791] [INFO] Watching for file changes with StatReloader
[2020-03-31 10:29:45,438] [ERROR] Internal Server Error: /
Traceback (most recent call last):
  File "C:\Users\lihua\AppData\Local\Programs\Python\Python37\lib\site-packages\django\core\handlers\exception.py", line 34, in inner
    response = get_response(request)
  File "C:\Users\lihua\AppData\Local\Programs\Python\Python37\lib\site-packages\django\core\handlers\base.py", line 115, in _get_response
    response = self.process_exception_by_middleware(e, request)
  File "C:\Users\lihua\AppData\Local\Programs\Python\Python37\lib\site-packages\django\core\handlers\base.py", line 113, in _get_response
    response = wrapped_callback(request, *callback_args, **callback_kwargs)
  File "E:\Data Processing Evaluation Tool\mysite\QCtool\views.py", line 29, in file_upload
    raise e
  File "E:\Data Processing Evaluation Tool\mysite\QCtool\views.py", line 27, in file_upload
    content = handle_uploaded_file(file, item, num, types)
  File "E:\Data Processing Evaluation Tool\mysite\QCtool\Item\handle.py", line 23, in handle_uploaded_file
    return vd.output()
  File "E:\Data Processing Evaluation Tool\mysite\QCtool\Item\VD.py", line 493, in output
    dic = self.get_dic_data()
  File "E:\Data Processing Evaluation Tool\mysite\QCtool\Item\VD.py", line 262, in get_dic_data
    dic = self.Agilent_data_format()
  File "E:\Data Processing Evaluation Tool\mysite\QCtool\Item\VD.py", line 185, in Agilent_data_format
    raise
RuntimeError: No active exception to reraise
[2020-03-31 10:29:45,571] [ERROR] "POST / HTTP/1.1" 500 127832
[2020-03-31 10:31:24,619] [INFO] E:\Data Processing Evaluation Tool\mysite\QCtool\Item\VD.py changed, reloading.
[2020-03-31 10:31:25,490] [INFO] Watching for file changes with StatReloader
[2020-03-31 10:31:34,212] [INFO] E:\Data Processing Evaluation Tool\mysite\QCtool\Item\VD.py changed, reloading.
[2020-03-31 10:31:35,080] [INFO] Watching for file changes with StatReloader
[2020-03-31 10:31:36,248] [ERROR] Internal Server Error: /
Traceback (most recent call last):
  File "C:\Users\lihua\AppData\Local\Programs\Python\Python37\lib\site-packages\django\core\handlers\exception.py", line 34, in inner
    response = get_response(request)
  File "C:\Users\lihua\AppData\Local\Programs\Python\Python37\lib\site-packages\django\core\handlers\base.py", line 115, in _get_response
    response = self.process_exception_by_middleware(e, request)
  File "C:\Users\lihua\AppData\Local\Programs\Python\Python37\lib\site-packages\django\core\handlers\base.py", line 113, in _get_response
    response = wrapped_callback(request, *callback_args, **callback_kwargs)
  File "E:\Data Processing Evaluation Tool\mysite\QCtool\views.py", line 29, in file_upload
    raise e
  File "E:\Data Processing Evaluation Tool\mysite\QCtool\views.py", line 27, in file_upload
    content = handle_uploaded_file(file, item, num, types)
  File "E:\Data Processing Evaluation Tool\mysite\QCtool\Item\handle.py", line 23, in handle_uploaded_file
    return vd.output()
  File "E:\Data Processing Evaluation Tool\mysite\QCtool\Item\VD.py", line 497, in output
    dic = self.get_dic_data()
  File "E:\Data Processing Evaluation Tool\mysite\QCtool\Item\VD.py", line 266, in get_dic_data
    dic = self.Agilent_data_format()
  File "E:\Data Processing Evaluation Tool\mysite\QCtool\Item\VD.py", line 189, in Agilent_data_format
    raise
RuntimeError: No active exception to reraise
[2020-03-31 10:31:36,382] [ERROR] "POST / HTTP/1.1" 500 127832
[2020-03-31 10:32:24,198] [INFO] E:\Data Processing Evaluation Tool\mysite\QCtool\Item\VD.py changed, reloading.
[2020-03-31 10:32:25,116] [INFO] Watching for file changes with StatReloader
[2020-03-31 10:32:25,674] [ERROR] Internal Server Error: /
Traceback (most recent call last):
  File "C:\Users\lihua\AppData\Local\Programs\Python\Python37\lib\site-packages\django\core\handlers\exception.py", line 34, in inner
    response = get_response(request)
  File "C:\Users\lihua\AppData\Local\Programs\Python\Python37\lib\site-packages\django\core\handlers\base.py", line 115, in _get_response
    response = self.process_exception_by_middleware(e, request)
  File "C:\Users\lihua\AppData\Local\Programs\Python\Python37\lib\site-packages\django\core\handlers\base.py", line 113, in _get_response
    response = wrapped_callback(request, *callback_args, **callback_kwargs)
  File "E:\Data Processing Evaluation Tool\mysite\QCtool\views.py", line 29, in file_upload
    raise e
  File "E:\Data Processing Evaluation Tool\mysite\QCtool\views.py", line 27, in file_upload
    content = handle_uploaded_file(file, item, num, types)
  File "E:\Data Processing Evaluation Tool\mysite\QCtool\Item\handle.py", line 23, in handle_uploaded_file
    return vd.output()
  File "E:\Data Processing Evaluation Tool\mysite\QCtool\Item\VD.py", line 498, in output
    dic = self.get_dic_data()
  File "E:\Data Processing Evaluation Tool\mysite\QCtool\Item\VD.py", line 267, in get_dic_data
    dic = self.Agilent_data_format()
  File "E:\Data Processing Evaluation Tool\mysite\QCtool\Item\VD.py", line 190, in Agilent_data_format
    raise
RuntimeError: No active exception to reraise
[2020-03-31 10:32:25,809] [ERROR] "POST / HTTP/1.1" 500 127832
[2020-03-31 10:33:18,445] [INFO] E:\Data Processing Evaluation Tool\mysite\QCtool\Item\VD.py changed, reloading.
[2020-03-31 10:33:19,359] [INFO] Watching for file changes with StatReloader
[2020-03-31 10:33:21,593] [ERROR] Internal Server Error: /
Traceback (most recent call last):
  File "C:\Users\lihua\AppData\Local\Programs\Python\Python37\lib\site-packages\django\core\handlers\exception.py", line 34, in inner
    response = get_response(request)
  File "C:\Users\lihua\AppData\Local\Programs\Python\Python37\lib\site-packages\django\core\handlers\base.py", line 115, in _get_response
    response = self.process_exception_by_middleware(e, request)
  File "C:\Users\lihua\AppData\Local\Programs\Python\Python37\lib\site-packages\django\core\handlers\base.py", line 113, in _get_response
    response = wrapped_callback(request, *callback_args, **callback_kwargs)
  File "E:\Data Processing Evaluation Tool\mysite\QCtool\views.py", line 29, in file_upload
    raise e
  File "E:\Data Processing Evaluation Tool\mysite\QCtool\views.py", line 27, in file_upload
    content = handle_uploaded_file(file, item, num, types)
  File "E:\Data Processing Evaluation Tool\mysite\QCtool\Item\handle.py", line 23, in handle_uploaded_file
    return vd.output()
  File "E:\Data Processing Evaluation Tool\mysite\QCtool\Item\VD.py", line 498, in output
    dic = self.get_dic_data()
  File "E:\Data Processing Evaluation Tool\mysite\QCtool\Item\VD.py", line 267, in get_dic_data
    dic = self.Agilent_data_format()
  File "E:\Data Processing Evaluation Tool\mysite\QCtool\Item\VD.py", line 190, in Agilent_data_format
    raise
RuntimeError: No active exception to reraise
[2020-03-31 10:33:21,728] [ERROR] "POST / HTTP/1.1" 500 127832
[2020-03-31 10:34:06,151] [INFO] E:\Data Processing Evaluation Tool\mysite\QCtool\Item\VD.py changed, reloading.
[2020-03-31 10:34:07,085] [INFO] Watching for file changes with StatReloader
[2020-03-31 10:34:07,691] [ERROR] Internal Server Error: /
Traceback (most recent call last):
  File "C:\Users\lihua\AppData\Local\Programs\Python\Python37\lib\site-packages\django\core\handlers\exception.py", line 34, in inner
    response = get_response(request)
  File "C:\Users\lihua\AppData\Local\Programs\Python\Python37\lib\site-packages\django\core\handlers\base.py", line 115, in _get_response
    response = self.process_exception_by_middleware(e, request)
  File "C:\Users\lihua\AppData\Local\Programs\Python\Python37\lib\site-packages\django\core\handlers\base.py", line 113, in _get_response
    response = wrapped_callback(request, *callback_args, **callback_kwargs)
  File "E:\Data Processing Evaluation Tool\mysite\QCtool\views.py", line 29, in file_upload
    raise e
  File "E:\Data Processing Evaluation Tool\mysite\QCtool\views.py", line 27, in file_upload
    content = handle_uploaded_file(file, item, num, types)
  File "E:\Data Processing Evaluation Tool\mysite\QCtool\Item\handle.py", line 23, in handle_uploaded_file
    return vd.output()
  File "E:\Data Processing Evaluation Tool\mysite\QCtool\Item\VD.py", line 499, in output
    dic = self.get_dic_data()
  File "E:\Data Processing Evaluation Tool\mysite\QCtool\Item\VD.py", line 268, in get_dic_data
    dic = self.Agilent_data_format()
  File "E:\Data Processing Evaluation Tool\mysite\QCtool\Item\VD.py", line 144, in Agilent_data_format
    raise
RuntimeError: No active exception to reraise
[2020-03-31 10:34:07,759] [ERROR] "POST / HTTP/1.1" 500 97135
[2020-03-31 10:35:01,778] [INFO] E:\Data Processing Evaluation Tool\mysite\QCtool\Item\VD.py changed, reloading.
[2020-03-31 10:35:02,698] [INFO] Watching for file changes with StatReloader
[2020-03-31 10:35:03,561] [ERROR] Internal Server Error: /
Traceback (most recent call last):
  File "C:\Users\lihua\AppData\Local\Programs\Python\Python37\lib\site-packages\django\core\handlers\exception.py", line 34, in inner
    response = get_response(request)
  File "C:\Users\lihua\AppData\Local\Programs\Python\Python37\lib\site-packages\django\core\handlers\base.py", line 115, in _get_response
    response = self.process_exception_by_middleware(e, request)
  File "C:\Users\lihua\AppData\Local\Programs\Python\Python37\lib\site-packages\django\core\handlers\base.py", line 113, in _get_response
    response = wrapped_callback(request, *callback_args, **callback_kwargs)
  File "E:\Data Processing Evaluation Tool\mysite\QCtool\views.py", line 29, in file_upload
    raise e
  File "E:\Data Processing Evaluation Tool\mysite\QCtool\views.py", line 27, in file_upload
    content = handle_uploaded_file(file, item, num, types)
  File "E:\Data Processing Evaluation Tool\mysite\QCtool\Item\handle.py", line 23, in handle_uploaded_file
    return vd.output()
  File "E:\Data Processing Evaluation Tool\mysite\QCtool\Item\VD.py", line 499, in output
    dic = self.get_dic_data()
  File "E:\Data Processing Evaluation Tool\mysite\QCtool\Item\VD.py", line 268, in get_dic_data
    dic = self.Agilent_data_format()
  File "E:\Data Processing Evaluation Tool\mysite\QCtool\Item\VD.py", line 143, in Agilent_data_format
    if Qualifier in title: raise
NameError: name 'Qualifier' is not defined
[2020-03-31 10:35:03,625] [ERROR] "POST / HTTP/1.1" 500 97161
[2020-03-31 10:35:11,698] [INFO] E:\Data Processing Evaluation Tool\mysite\QCtool\Item\VD.py changed, reloading.
[2020-03-31 10:35:12,581] [INFO] Watching for file changes with StatReloader
[2020-03-31 10:35:13,122] [ERROR] Internal Server Error: /
Traceback (most recent call last):
  File "C:\Users\lihua\AppData\Local\Programs\Python\Python37\lib\site-packages\django\core\handlers\exception.py", line 34, in inner
    response = get_response(request)
  File "C:\Users\lihua\AppData\Local\Programs\Python\Python37\lib\site-packages\django\core\handlers\base.py", line 115, in _get_response
    response = self.process_exception_by_middleware(e, request)
  File "C:\Users\lihua\AppData\Local\Programs\Python\Python37\lib\site-packages\django\core\handlers\base.py", line 113, in _get_response
    response = wrapped_callback(request, *callback_args, **callback_kwargs)
  File "E:\Data Processing Evaluation Tool\mysite\QCtool\views.py", line 29, in file_upload
    raise e
  File "E:\Data Processing Evaluation Tool\mysite\QCtool\views.py", line 27, in file_upload
    content = handle_uploaded_file(file, item, num, types)
  File "E:\Data Processing Evaluation Tool\mysite\QCtool\Item\handle.py", line 23, in handle_uploaded_file
    return vd.output()
  File "E:\Data Processing Evaluation Tool\mysite\QCtool\Item\VD.py", line 499, in output
    dic = self.get_dic_data()
  File "E:\Data Processing Evaluation Tool\mysite\QCtool\Item\VD.py", line 268, in get_dic_data
    dic = self.Agilent_data_format()
  File "E:\Data Processing Evaluation Tool\mysite\QCtool\Item\VD.py", line 143, in Agilent_data_format
    if "Qualifier" in title: raise
RuntimeError: No active exception to reraise
[2020-03-31 10:35:13,189] [ERROR] "POST / HTTP/1.1" 500 97488
[2020-03-31 10:39:35,643] [INFO] E:\Data Processing Evaluation Tool\mysite\QCtool\Item\VD.py changed, reloading.
[2020-03-31 10:39:37,870] [INFO] Watching for file changes with StatReloader
[2020-03-31 10:40:11,344] [INFO] E:\Data Processing Evaluation Tool\mysite\QCtool\Item\VD.py changed, reloading.
[2020-03-31 10:40:16,747] [INFO] Watching for file changes with StatReloader
[2020-03-31 10:41:04,592] [INFO] E:\Data Processing Evaluation Tool\mysite\QCtool\Item\VD.py changed, reloading.
[2020-03-31 10:41:05,473] [INFO] Watching for file changes with StatReloader
[2020-03-31 10:41:07,133] [ERROR] Internal Server Error: /
Traceback (most recent call last):
  File "C:\Users\lihua\AppData\Local\Programs\Python\Python37\lib\site-packages\django\core\handlers\exception.py", line 34, in inner
    response = get_response(request)
  File "C:\Users\lihua\AppData\Local\Programs\Python\Python37\lib\site-packages\django\core\handlers\base.py", line 115, in _get_response
    response = self.process_exception_by_middleware(e, request)
  File "C:\Users\lihua\AppData\Local\Programs\Python\Python37\lib\site-packages\django\core\handlers\base.py", line 113, in _get_response
    response = wrapped_callback(request, *callback_args, **callback_kwargs)
  File "E:\Data Processing Evaluation Tool\mysite\QCtool\views.py", line 29, in file_upload
    raise e
  File "E:\Data Processing Evaluation Tool\mysite\QCtool\views.py", line 27, in file_upload
    content = handle_uploaded_file(file, item, num, types)
  File "E:\Data Processing Evaluation Tool\mysite\QCtool\Item\handle.py", line 23, in handle_uploaded_file
    return vd.output()
  File "E:\Data Processing Evaluation Tool\mysite\QCtool\Item\VD.py", line 498, in output
    dic = self.get_dic_data()
  File "E:\Data Processing Evaluation Tool\mysite\QCtool\Item\VD.py", line 267, in get_dic_data
    dic = self.Agilent_data_format()
  File "E:\Data Processing Evaluation Tool\mysite\QCtool\Item\VD.py", line 190, in Agilent_data_format
    raise
RuntimeError: No active exception to reraise
[2020-03-31 10:41:07,267] [ERROR] "POST / HTTP/1.1" 500 127832
[2020-03-31 10:41:42,773] [INFO] E:\Data Processing Evaluation Tool\mysite\QCtool\Item\VD.py changed, reloading.
[2020-03-31 10:41:43,657] [INFO] Watching for file changes with StatReloader
[2020-03-31 10:41:44,502] [INFO] 提交数据:YZ06-20200317.csv
[2020-03-31 10:41:44,559] [INFO] "POST / HTTP/1.1" 200 33328
[2020-03-31 10:42:23,999] [INFO] E:\Data Processing Evaluation Tool\mysite\QCtool\Item\VD.py changed, reloading.
[2020-03-31 10:42:24,869] [INFO] Watching for file changes with StatReloader
[2020-03-31 10:42:25,956] [ERROR] Internal Server Error: /
Traceback (most recent call last):
  File "C:\Users\lihua\AppData\Local\Programs\Python\Python37\lib\site-packages\django\core\handlers\exception.py", line 34, in inner
    response = get_response(request)
  File "C:\Users\lihua\AppData\Local\Programs\Python\Python37\lib\site-packages\django\core\handlers\base.py", line 115, in _get_response
    response = self.process_exception_by_middleware(e, request)
  File "C:\Users\lihua\AppData\Local\Programs\Python\Python37\lib\site-packages\django\core\handlers\base.py", line 113, in _get_response
    response = wrapped_callback(request, *callback_args, **callback_kwargs)
  File "E:\Data Processing Evaluation Tool\mysite\QCtool\views.py", line 29, in file_upload
    raise e
  File "E:\Data Processing Evaluation Tool\mysite\QCtool\views.py", line 27, in file_upload
    content = handle_uploaded_file(file, item, num, types)
  File "E:\Data Processing Evaluation Tool\mysite\QCtool\Item\handle.py", line 23, in handle_uploaded_file
    return vd.output()
  File "E:\Data Processing Evaluation Tool\mysite\QCtool\Item\VD.py", line 497, in output
    dic = self.get_dic_data()
  File "E:\Data Processing Evaluation Tool\mysite\QCtool\Item\VD.py", line 266, in get_dic_data
    dic = self.Agilent_data_format()
  File "E:\Data Processing Evaluation Tool\mysite\QCtool\Item\VD.py", line 143, in Agilent_data_format
    if "Qualifier" in h[0]: raise
RuntimeError: No active exception to reraise
[2020-03-31 10:42:26,020] [ERROR] "POST / HTTP/1.1" 500 97471
[2020-03-31 10:43:26,643] [INFO] E:\Data Processing Evaluation Tool\mysite\QCtool\Item\VD.py changed, reloading.
[2020-03-31 10:43:27,424] [INFO] Watching for file changes with StatReloader
[2020-03-31 10:43:51,816] [INFO] E:\Data Processing Evaluation Tool\mysite\QCtool\Item\VD.py changed, reloading.
[2020-03-31 10:43:53,786] [INFO] Watching for file changes with StatReloader
[2020-03-31 10:43:57,327] [INFO] E:\Data Processing Evaluation Tool\mysite\QCtool\Item\VD.py changed, reloading.
[2020-03-31 10:43:59,041] [INFO] Watching for file changes with StatReloader
[2020-03-31 10:44:01,713] [INFO] "GET / HTTP/1.1" 200 3290
[2020-03-31 10:44:10,802] [ERROR] Internal Server Error: /
Traceback (most recent call last):
  File "C:\Users\lihua\AppData\Local\Programs\Python\Python37\lib\site-packages\django\core\handlers\exception.py", line 34, in inner
    response = get_response(request)
  File "C:\Users\lihua\AppData\Local\Programs\Python\Python37\lib\site-packages\django\core\handlers\base.py", line 115, in _get_response
    response = self.process_exception_by_middleware(e, request)
  File "C:\Users\lihua\AppData\Local\Programs\Python\Python37\lib\site-packages\django\core\handlers\base.py", line 113, in _get_response
    response = wrapped_callback(request, *callback_args, **callback_kwargs)
  File "E:\Data Processing Evaluation Tool\mysite\QCtool\views.py", line 29, in file_upload
    raise e
  File "E:\Data Processing Evaluation Tool\mysite\QCtool\views.py", line 27, in file_upload
    content = handle_uploaded_file(file, item, num, types)
  File "E:\Data Processing Evaluation Tool\mysite\QCtool\Item\handle.py", line 23, in handle_uploaded_file
    return vd.output()
  File "E:\Data Processing Evaluation Tool\mysite\QCtool\Item\VD.py", line 496, in output
    dic = self.get_dic_data()
  File "E:\Data Processing Evaluation Tool\mysite\QCtool\Item\VD.py", line 265, in get_dic_data
    dic = self.Agilent_data_format()
  File "E:\Data Processing Evaluation Tool\mysite\QCtool\Item\VD.py", line 162, in Agilent_data_format
    raise
RuntimeError: No active exception to reraise
[2020-03-31 10:44:10,872] [ERROR] "POST / HTTP/1.1" 500 97612
[2020-03-31 10:45:14,353] [INFO] E:\Data Processing Evaluation Tool\mysite\QCtool\Item\VD.py changed, reloading.
[2020-03-31 10:45:15,215] [INFO] Watching for file changes with StatReloader
[2020-03-31 10:45:24,073] [INFO] E:\Data Processing Evaluation Tool\mysite\QCtool\Item\VD.py changed, reloading.
[2020-03-31 10:45:24,893] [INFO] Watching for file changes with StatReloader
[2020-03-31 10:45:33,647] [INFO] E:\Data Processing Evaluation Tool\mysite\QCtool\Item\VD.py changed, reloading.
[2020-03-31 10:45:34,551] [INFO] Watching for file changes with StatReloader
[2020-03-31 10:45:36,711] [INFO] 提交数据:YZ06-20200317.csv
[2020-03-31 10:45:36,772] [INFO] "POST / HTTP/1.1" 200 37193
[2020-03-31 10:45:57,037] [INFO] E:\Data Processing Evaluation Tool\mysite\QCtool\Item\VD.py changed, reloading.
[2020-03-31 10:45:57,936] [INFO] Watching for file changes with StatReloader
[2020-03-31 10:46:00,057] [INFO] 提交数据:YZ06-20200317.csv
[2020-03-31 10:46:00,120] [INFO] "POST / HTTP/1.1" 200 37193
[2020-03-31 10:46:06,006] [INFO] E:\Data Processing Evaluation Tool\mysite\QCtool\Item\VD.py changed, reloading.
[2020-03-31 10:46:07,011] [INFO] Watching for file changes with StatReloader
[2020-03-31 10:46:09,165] [INFO] 提交数据:YZ06-20200317.csv
[2020-03-31 10:46:09,221] [INFO] "POST / HTTP/1.1" 200 37193
[2020-03-31 10:46:12,472] [INFO] E:\Data Processing Evaluation Tool\mysite\QCtool\Item\VD.py changed, reloading.
[2020-03-31 10:46:13,378] [INFO] Watching for file changes with StatReloader
[2020-03-31 10:46:24,902] [INFO] E:\Data Processing Evaluation Tool\mysite\QCtool\Item\VD.py changed, reloading.
[2020-03-31 10:46:25,769] [INFO] Watching for file changes with StatReloader
[2020-03-31 10:46:28,069] [INFO] E:\Data Processing Evaluation Tool\mysite\QCtool\Item\VD.py changed, reloading.
[2020-03-31 10:46:28,903] [INFO] Watching for file changes with StatReloader
[2020-03-31 10:46:29,662] [ERROR] Internal Server Error: /
Traceback (most recent call last):
  File "C:\Users\lihua\AppData\Local\Programs\Python\Python37\lib\site-packages\django\core\handlers\exception.py", line 34, in inner
    response = get_response(request)
  File "C:\Users\lihua\AppData\Local\Programs\Python\Python37\lib\site-packages\django\core\handlers\base.py", line 115, in _get_response
    response = self.process_exception_by_middleware(e, request)
  File "C:\Users\lihua\AppData\Local\Programs\Python\Python37\lib\site-packages\django\core\handlers\base.py", line 113, in _get_response
    response = wrapped_callback(request, *callback_args, **callback_kwargs)
  File "E:\Data Processing Evaluation Tool\mysite\QCtool\views.py", line 29, in file_upload
    raise e
  File "E:\Data Processing Evaluation Tool\mysite\QCtool\views.py", line 27, in file_upload
    content = handle_uploaded_file(file, item, num, types)
  File "E:\Data Processing Evaluation Tool\mysite\QCtool\Item\handle.py", line 23, in handle_uploaded_file
    return vd.output()
  File "E:\Data Processing Evaluation Tool\mysite\QCtool\Item\VD.py", line 497, in output
    dic = self.get_dic_data()
  File "E:\Data Processing Evaluation Tool\mysite\QCtool\Item\VD.py", line 266, in get_dic_data
    dic = self.Agilent_data_format()
  File "E:\Data Processing Evaluation Tool\mysite\QCtool\Item\VD.py", line 153, in Agilent_data_format
    raise
RuntimeError: No active exception to reraise
[2020-03-31 10:46:29,725] [ERROR] "POST / HTTP/1.1" 500 97528
[2020-03-31 10:46:54,610] [INFO] E:\Data Processing Evaluation Tool\mysite\QCtool\Item\VD.py changed, reloading.
[2020-03-31 10:46:55,386] [INFO] Watching for file changes with StatReloader
[2020-03-31 10:47:06,843] [INFO] E:\Data Processing Evaluation Tool\mysite\QCtool\Item\VD.py changed, reloading.
[2020-03-31 10:47:07,810] [INFO] Watching for file changes with StatReloader
[2020-03-31 10:47:08,623] [ERROR] Internal Server Error: /
Traceback (most recent call last):
  File "C:\Users\lihua\AppData\Local\Programs\Python\Python37\lib\site-packages\django\core\handlers\exception.py", line 34, in inner
    response = get_response(request)
  File "C:\Users\lihua\AppData\Local\Programs\Python\Python37\lib\site-packages\django\core\handlers\base.py", line 115, in _get_response
    response = self.process_exception_by_middleware(e, request)
  File "C:\Users\lihua\AppData\Local\Programs\Python\Python37\lib\site-packages\django\core\handlers\base.py", line 113, in _get_response
    response = wrapped_callback(request, *callback_args, **callback_kwargs)
  File "E:\Data Processing Evaluation Tool\mysite\QCtool\views.py", line 29, in file_upload
    raise e
  File "E:\Data Processing Evaluation Tool\mysite\QCtool\views.py", line 27, in file_upload
    content = handle_uploaded_file(file, item, num, types)
  File "E:\Data Processing Evaluation Tool\mysite\QCtool\Item\handle.py", line 23, in handle_uploaded_file
    return vd.output()
  File "E:\Data Processing Evaluation Tool\mysite\QCtool\Item\VD.py", line 497, in output
    dic = self.get_dic_data()
  File "E:\Data Processing Evaluation Tool\mysite\QCtool\Item\VD.py", line 266, in get_dic_data
    dic = self.Agilent_data_format()
  File "E:\Data Processing Evaluation Tool\mysite\QCtool\Item\VD.py", line 153, in Agilent_data_format
    raise
RuntimeError: No active exception to reraise
[2020-03-31 10:47:08,687] [ERROR] "POST / HTTP/1.1" 500 97722
[2020-03-31 10:47:32,373] [INFO] E:\Data Processing Evaluation Tool\mysite\QCtool\Item\VD.py changed, reloading.
[2020-03-31 10:47:33,233] [INFO] Watching for file changes with StatReloader
[2020-03-31 10:47:34,229] [ERROR] Internal Server Error: /
Traceback (most recent call last):
  File "C:\Users\lihua\AppData\Local\Programs\Python\Python37\lib\site-packages\django\core\handlers\exception.py", line 34, in inner
    response = get_response(request)
  File "C:\Users\lihua\AppData\Local\Programs\Python\Python37\lib\site-packages\django\core\handlers\base.py", line 115, in _get_response
    response = self.process_exception_by_middleware(e, request)
  File "C:\Users\lihua\AppData\Local\Programs\Python\Python37\lib\site-packages\django\core\handlers\base.py", line 113, in _get_response
    response = wrapped_callback(request, *callback_args, **callback_kwargs)
  File "E:\Data Processing Evaluation Tool\mysite\QCtool\views.py", line 29, in file_upload
    raise e
  File "E:\Data Processing Evaluation Tool\mysite\QCtool\views.py", line 27, in file_upload
    content = handle_uploaded_file(file, item, num, types)
  File "E:\Data Processing Evaluation Tool\mysite\QCtool\Item\handle.py", line 23, in handle_uploaded_file
    return vd.output()
  File "E:\Data Processing Evaluation Tool\mysite\QCtool\Item\VD.py", line 497, in output
    dic = self.get_dic_data()
  File "E:\Data Processing Evaluation Tool\mysite\QCtool\Item\VD.py", line 266, in get_dic_data
    dic = self.Agilent_data_format()
  File "E:\Data Processing Evaluation Tool\mysite\QCtool\Item\VD.py", line 163, in Agilent_data_format
    raise
RuntimeError: No active exception to reraise
[2020-03-31 10:47:34,297] [ERROR] "POST / HTTP/1.1" 500 97614
[2020-03-31 10:48:05,477] [INFO] E:\Data Processing Evaluation Tool\mysite\QCtool\Item\VD.py changed, reloading.
[2020-03-31 10:48:06,323] [INFO] Watching for file changes with StatReloader
[2020-03-31 10:48:15,935] [ERROR] Internal Server Error: /
Traceback (most recent call last):
  File "C:\Users\lihua\AppData\Local\Programs\Python\Python37\lib\site-packages\django\core\handlers\exception.py", line 34, in inner
    response = get_response(request)
  File "C:\Users\lihua\AppData\Local\Programs\Python\Python37\lib\site-packages\django\core\handlers\base.py", line 115, in _get_response
    response = self.process_exception_by_middleware(e, request)
  File "C:\Users\lihua\AppData\Local\Programs\Python\Python37\lib\site-packages\django\core\handlers\base.py", line 113, in _get_response
    response = wrapped_callback(request, *callback_args, **callback_kwargs)
  File "E:\Data Processing Evaluation Tool\mysite\QCtool\views.py", line 29, in file_upload
    raise e
  File "E:\Data Processing Evaluation Tool\mysite\QCtool\views.py", line 27, in file_upload
    content = handle_uploaded_file(file, item, num, types)
  File "E:\Data Processing Evaluation Tool\mysite\QCtool\Item\handle.py", line 23, in handle_uploaded_file
    return vd.output()
  File "E:\Data Processing Evaluation Tool\mysite\QCtool\Item\VD.py", line 497, in output
    dic = self.get_dic_data()
  File "E:\Data Processing Evaluation Tool\mysite\QCtool\Item\VD.py", line 266, in get_dic_data
    dic = self.Agilent_data_format()
  File "E:\Data Processing Evaluation Tool\mysite\QCtool\Item\VD.py", line 163, in Agilent_data_format
    raise
RuntimeError: No active exception to reraise
[2020-03-31 10:48:15,999] [ERROR] "POST / HTTP/1.1" 500 97609
[2020-03-31 10:48:35,051] [INFO] E:\Data Processing Evaluation Tool\mysite\QCtool\Item\VD.py changed, reloading.
[2020-03-31 10:48:35,887] [INFO] Watching for file changes with StatReloader
[2020-03-31 10:48:44,728] [INFO] E:\Data Processing Evaluation Tool\mysite\QCtool\Item\VD.py changed, reloading.
[2020-03-31 10:48:45,597] [INFO] Watching for file changes with StatReloader
[2020-03-31 10:48:55,630] [INFO] E:\Data Processing Evaluation Tool\mysite\QCtool\Item\VD.py changed, reloading.
[2020-03-31 10:48:56,514] [INFO] Watching for file changes with StatReloader
[2020-03-31 10:48:57,143] [ERROR] Internal Server Error: /
Traceback (most recent call last):
  File "C:\Users\lihua\AppData\Local\Programs\Python\Python37\lib\site-packages\django\core\handlers\exception.py", line 34, in inner
    response = get_response(request)
  File "C:\Users\lihua\AppData\Local\Programs\Python\Python37\lib\site-packages\django\core\handlers\base.py", line 115, in _get_response
    response = self.process_exception_by_middleware(e, request)
  File "C:\Users\lihua\AppData\Local\Programs\Python\Python37\lib\site-packages\django\core\handlers\base.py", line 113, in _get_response
    response = wrapped_callback(request, *callback_args, **callback_kwargs)
  File "E:\Data Processing Evaluation Tool\mysite\QCtool\views.py", line 29, in file_upload
    raise e
  File "E:\Data Processing Evaluation Tool\mysite\QCtool\views.py", line 27, in file_upload
    content = handle_uploaded_file(file, item, num, types)
  File "E:\Data Processing Evaluation Tool\mysite\QCtool\Item\handle.py", line 23, in handle_uploaded_file
    return vd.output()
  File "E:\Data Processing Evaluation Tool\mysite\QCtool\Item\VD.py", line 498, in output
    dic = self.get_dic_data()
  File "E:\Data Processing Evaluation Tool\mysite\QCtool\Item\VD.py", line 267, in get_dic_data
    dic = self.Agilent_data_format()
  File "E:\Data Processing Evaluation Tool\mysite\QCtool\Item\VD.py", line 190, in Agilent_data_format
    raise
RuntimeError: No active exception to reraise
[2020-03-31 10:48:57,279] [ERROR] "POST / HTTP/1.1" 500 127836
[2020-03-31 10:49:59,087] [INFO] E:\Data Processing Evaluation Tool\mysite\QCtool\Item\VD.py changed, reloading.
[2020-03-31 10:49:59,918] [INFO] Watching for file changes with StatReloader
[2020-03-31 10:50:15,167] [INFO] E:\Data Processing Evaluation Tool\mysite\QCtool\Item\VD.py changed, reloading.
[2020-03-31 10:50:16,045] [INFO] Watching for file changes with StatReloader
[2020-03-31 10:50:24,741] [INFO] E:\Data Processing Evaluation Tool\mysite\QCtool\Item\VD.py changed, reloading.
[2020-03-31 10:50:25,582] [INFO] Watching for file changes with StatReloader
[2020-03-31 10:50:26,315] [ERROR] Internal Server Error: /
Traceback (most recent call last):
  File "C:\Users\lihua\AppData\Local\Programs\Python\Python37\lib\site-packages\django\core\handlers\exception.py", line 34, in inner
    response = get_response(request)
  File "C:\Users\lihua\AppData\Local\Programs\Python\Python37\lib\site-packages\django\core\handlers\base.py", line 115, in _get_response
    response = self.process_exception_by_middleware(e, request)
  File "C:\Users\lihua\AppData\Local\Programs\Python\Python37\lib\site-packages\django\core\handlers\base.py", line 113, in _get_response
    response = wrapped_callback(request, *callback_args, **callback_kwargs)
  File "E:\Data Processing Evaluation Tool\mysite\QCtool\views.py", line 29, in file_upload
    raise e
  File "E:\Data Processing Evaluation Tool\mysite\QCtool\views.py", line 27, in file_upload
    content = handle_uploaded_file(file, item, num, types)
  File "E:\Data Processing Evaluation Tool\mysite\QCtool\Item\handle.py", line 23, in handle_uploaded_file
    return vd.output()
  File "E:\Data Processing Evaluation Tool\mysite\QCtool\Item\VD.py", line 498, in output
    dic = self.get_dic_data()
  File "E:\Data Processing Evaluation Tool\mysite\QCtool\Item\VD.py", line 267, in get_dic_data
    dic = self.Agilent_data_format()
  File "E:\Data Processing Evaluation Tool\mysite\QCtool\Item\VD.py", line 190, in Agilent_data_format
    raise
RuntimeError: No active exception to reraise
[2020-03-31 10:50:26,451] [ERROR] "POST / HTTP/1.1" 500 127834
[2020-03-31 10:50:50,529] [INFO] E:\Data Processing Evaluation Tool\mysite\QCtool\Item\VD.py changed, reloading.
[2020-03-31 10:50:51,403] [INFO] Watching for file changes with StatReloader
[2020-03-31 10:51:27,323] [INFO] E:\Data Processing Evaluation Tool\mysite\QCtool\main.py changed, reloading.
[2020-03-31 10:51:28,160] [INFO] Watching for file changes with StatReloader
[2020-03-31 10:51:54,939] [INFO] E:\Data Processing Evaluation Tool\mysite\QCtool\main.py changed, reloading.
[2020-03-31 10:51:55,739] [INFO] Watching for file changes with StatReloader
[2020-03-31 10:53:32,122] [INFO] E:\Data Processing Evaluation Tool\mysite\QCtool\main.py changed, reloading.
[2020-03-31 10:53:34,615] [INFO] Watching for file changes with StatReloader
[2020-03-31 10:53:40,775] [INFO] E:\Data Processing Evaluation Tool\mysite\QCtool\main.py changed, reloading.
[2020-03-31 10:53:41,564] [INFO] Watching for file changes with StatReloader
[2020-03-31 10:53:56,736] [INFO] E:\Data Processing Evaluation Tool\mysite\QCtool\main.py changed, reloading.
[2020-03-31 10:53:57,567] [INFO] Watching for file changes with StatReloader
[2020-03-31 10:54:29,779] [INFO] E:\Data Processing Evaluation Tool\mysite\QCtool\main.py changed, reloading.
[2020-03-31 10:54:30,596] [INFO] Watching for file changes with StatReloader
[2020-03-31 10:55:11,570] [INFO] E:\Data Processing Evaluation Tool\mysite\QCtool\main.py changed, reloading.
[2020-03-31 10:55:12,378] [INFO] Watching for file changes with StatReloader
[2020-03-31 10:55:25,263] [INFO] E:\Data Processing Evaluation Tool\mysite\QCtool\main.py changed, reloading.
[2020-03-31 10:55:26,129] [INFO] Watching for file changes with StatReloader
[2020-03-31 10:55:49,581] [INFO] E:\Data Processing Evaluation Tool\mysite\QCtool\main.py changed, reloading.
[2020-03-31 10:55:50,438] [INFO] Watching for file changes with StatReloader
[2020-03-31 10:56:05,792] [INFO] E:\Data Processing Evaluation Tool\mysite\QCtool\main.py changed, reloading.
[2020-03-31 10:56:06,614] [INFO] Watching for file changes with StatReloader
[2020-03-31 10:58:27,021] [INFO] E:\Data Processing Evaluation Tool\mysite\QCtool\main.py changed, reloading.
[2020-03-31 10:58:27,869] [INFO] Watching for file changes with StatReloader
[2020-03-31 11:00:44,476] [INFO] E:\Data Processing Evaluation Tool\mysite\QCtool\main.py changed, reloading.
[2020-03-31 11:00:45,327] [INFO] Watching for file changes with StatReloader
[2020-03-31 11:01:43,624] [INFO] E:\Data Processing Evaluation Tool\mysite\QCtool\main.py changed, reloading.
[2020-03-31 11:01:44,494] [INFO] Watching for file changes with StatReloader
[2020-03-31 11:03:28,636] [INFO] E:\Data Processing Evaluation Tool\mysite\QCtool\main.py changed, reloading.
[2020-03-31 11:03:29,489] [INFO] Watching for file changes with StatReloader
[2020-03-31 11:03:44,840] [INFO] E:\Data Processing Evaluation Tool\mysite\QCtool\main.py changed, reloading.
[2020-03-31 11:03:45,738] [INFO] Watching for file changes with StatReloader
[2020-03-31 11:04:49,287] [INFO] E:\Data Processing Evaluation Tool\mysite\QCtool\main.py changed, reloading.
[2020-03-31 11:04:51,199] [INFO] Watching for file changes with StatReloader
[2020-03-31 11:04:54,799] [INFO] E:\Data Processing Evaluation Tool\mysite\QCtool\main.py changed, reloading.
[2020-03-31 11:04:55,665] [INFO] Watching for file changes with StatReloader
[2020-03-31 11:05:18,685] [INFO] E:\Data Processing Evaluation Tool\mysite\QCtool\main.py changed, reloading.
[2020-03-31 11:05:19,529] [INFO] Watching for file changes with StatReloader
[2020-03-31 11:05:32,188] [INFO] E:\Data Processing Evaluation Tool\mysite\QCtool\main.py changed, reloading.
[2020-03-31 11:05:33,041] [INFO] Watching for file changes with StatReloader
[2020-03-31 11:05:52,287] [INFO] E:\Data Processing Evaluation Tool\mysite\QCtool\main.py changed, reloading.
[2020-03-31 11:05:53,153] [INFO] Watching for file changes with StatReloader
[2020-03-31 11:06:04,521] [INFO] E:\Data Processing Evaluation Tool\mysite\QCtool\main.py changed, reloading.
[2020-03-31 11:06:05,392] [INFO] Watching for file changes with StatReloader
[2020-03-31 11:06:24,551] [INFO] E:\Data Processing Evaluation Tool\mysite\QCtool\main.py changed, reloading.
[2020-03-31 11:06:25,369] [INFO] Watching for file changes with StatReloader
[2020-03-31 11:06:44,737] [INFO] E:\Data Processing Evaluation Tool\mysite\QCtool\main.py changed, reloading.
[2020-03-31 11:06:45,617] [INFO] Watching for file changes with StatReloader
[2020-03-31 11:08:03,786] [INFO] E:\Data Processing Evaluation Tool\mysite\QCtool\main.py changed, reloading.
[2020-03-31 11:08:04,612] [INFO] Watching for file changes with StatReloader
[2020-03-31 11:08:51,015] [INFO] E:\Data Processing Evaluation Tool\mysite\QCtool\main.py changed, reloading.
[2020-03-31 11:08:51,862] [INFO] Watching for file changes with StatReloader
[2020-03-31 11:09:46,675] [INFO] E:\Data Processing Evaluation Tool\mysite\QCtool\main.py changed, reloading.
[2020-03-31 11:09:47,539] [INFO] Watching for file changes with StatReloader
[2020-03-31 11:10:31,518] [INFO] E:\Data Processing Evaluation Tool\mysite\QCtool\main.py changed, reloading.
[2020-03-31 11:10:32,395] [INFO] Watching for file changes with StatReloader
[2020-03-31 11:11:40,330] [INFO] E:\Data Processing Evaluation Tool\mysite\QCtool\Item\VD.py changed, reloading.
[2020-03-31 11:11:41,200] [INFO] Watching for file changes with StatReloader
[2020-03-31 11:13:47,702] [INFO] E:\Data Processing Evaluation Tool\mysite\QCtool\Item\VD.py changed, reloading.
[2020-03-31 11:13:48,553] [INFO] Watching for file changes with StatReloader
[2020-03-31 11:14:03,892] [INFO] E:\Data Processing Evaluation Tool\mysite\QCtool\Item\VD.py changed, reloading.
[2020-03-31 11:14:04,765] [INFO] Watching for file changes with StatReloader
[2020-03-31 11:14:11,116] [INFO] E:\Data Processing Evaluation Tool\mysite\QCtool\Item\VD.py changed, reloading.
[2020-03-31 11:14:11,962] [INFO] Watching for file changes with StatReloader
[2020-03-31 11:14:22,221] [INFO] E:\Data Processing Evaluation Tool\mysite\QCtool\Item\VD.py changed, reloading.
[2020-03-31 11:14:23,064] [INFO] Watching for file changes with StatReloader
[2020-03-31 11:14:25,418] [INFO] E:\Data Processing Evaluation Tool\mysite\QCtool\Item\VD.py changed, reloading.
[2020-03-31 11:14:26,266] [INFO] Watching for file changes with StatReloader
[2020-03-31 11:14:36,543] [INFO] E:\Data Processing Evaluation Tool\mysite\QCtool\Item\VD.py changed, reloading.
[2020-03-31 11:14:38,622] [INFO] Watching for file changes with StatReloader
[2020-03-31 11:14:50,170] [INFO] E:\Data Processing Evaluation Tool\mysite\QCtool\Item\VD.py changed, reloading.
[2020-03-31 11:14:51,066] [INFO] Watching for file changes with StatReloader
[2020-03-31 11:14:56,453] [ERROR] Internal Server Error: /
Traceback (most recent call last):
  File "C:\Users\lihua\AppData\Local\Programs\Python\Python37\lib\site-packages\django\core\handlers\exception.py", line 34, in inner
    response = get_response(request)
  File "C:\Users\lihua\AppData\Local\Programs\Python\Python37\lib\site-packages\django\core\handlers\base.py", line 115, in _get_response
    response = self.process_exception_by_middleware(e, request)
  File "C:\Users\lihua\AppData\Local\Programs\Python\Python37\lib\site-packages\django\core\handlers\base.py", line 113, in _get_response
    response = wrapped_callback(request, *callback_args, **callback_kwargs)
  File "E:\Data Processing Evaluation Tool\mysite\QCtool\views.py", line 29, in file_upload
    raise e
  File "E:\Data Processing Evaluation Tool\mysite\QCtool\views.py", line 27, in file_upload
    content = handle_uploaded_file(file, item, num, types)
  File "E:\Data Processing Evaluation Tool\mysite\QCtool\Item\handle.py", line 23, in handle_uploaded_file
    return vd.output()
  File "E:\Data Processing Evaluation Tool\mysite\QCtool\Item\VD.py", line 495, in output
    dic = self.get_dic_data()
  File "E:\Data Processing Evaluation Tool\mysite\QCtool\Item\VD.py", line 267, in get_dic_data
    dic = self.Agilent_data_format()
  File "E:\Data Processing Evaluation Tool\mysite\QCtool\Item\VD.py", line 190, in Agilent_data_format
    raise
RuntimeError: No active exception to reraise
[2020-03-31 11:14:56,598] [ERROR] "POST / HTTP/1.1" 500 127834
[2020-03-31 11:15:09,933] [INFO] E:\Data Processing Evaluation Tool\mysite\QCtool\Item\VD.py changed, reloading.
[2020-03-31 11:15:10,792] [INFO] Watching for file changes with StatReloader
[2020-03-31 11:15:38,203] [ERROR] Internal Server Error: /
Traceback (most recent call last):
  File "C:\Users\lihua\AppData\Local\Programs\Python\Python37\lib\site-packages\django\core\handlers\exception.py", line 34, in inner
    response = get_response(request)
  File "C:\Users\lihua\AppData\Local\Programs\Python\Python37\lib\site-packages\django\core\handlers\base.py", line 115, in _get_response
    response = self.process_exception_by_middleware(e, request)
  File "C:\Users\lihua\AppData\Local\Programs\Python\Python37\lib\site-packages\django\core\handlers\base.py", line 113, in _get_response
    response = wrapped_callback(request, *callback_args, **callback_kwargs)
  File "E:\Data Processing Evaluation Tool\mysite\QCtool\views.py", line 29, in file_upload
    raise e
  File "E:\Data Processing Evaluation Tool\mysite\QCtool\views.py", line 27, in file_upload
    content = handle_uploaded_file(file, item, num, types)
  File "E:\Data Processing Evaluation Tool\mysite\QCtool\Item\handle.py", line 23, in handle_uploaded_file
    return vd.output()
  File "E:\Data Processing Evaluation Tool\mysite\QCtool\Item\VD.py", line 614, in output
    output["d2_Ion_Ratio"] = self.get_Ion_Ratio(dic[self.D2], self.D2_LLMI, self.instrument_prefix + self.instrument_num, self.D2)
  File "E:\Data Processing Evaluation Tool\mysite\QCtool\main.py", line 613, in get_Ion_Ratio
    IonRatio = IonRatioFrame.objects.filter(instrument=instrument, item=item)[0]
  File "C:\Users\lihua\AppData\Local\Programs\Python\Python37\lib\site-packages\django\db\models\query.py", line 309, in __getitem__
    return qs._result_cache[0]
IndexError: list index out of range
[2020-03-31 11:15:38,338] [ERROR] "POST / HTTP/1.1" 500 132097
[2020-03-31 11:16:04,385] [INFO] "GET /admin/QCtool/ionratioframe/ HTTP/1.1" 200 5643
[2020-03-31 11:16:04,405] [INFO] "GET /admin/jsi18n/ HTTP/1.1" 200 7722
[2020-03-31 11:16:05,636] [INFO] "GET /admin/QCtool/ionratioframe/2/change/ HTTP/1.1" 200 5282
[2020-03-31 11:16:05,653] [INFO] "GET /admin/jsi18n/ HTTP/1.1" 200 7722
[2020-03-31 11:16:14,058] [INFO] "POST /admin/QCtool/ionratioframe/2/change/ HTTP/1.1" 302 0
[2020-03-31 11:16:14,124] [INFO] "GET /admin/QCtool/ionratioframe/ HTTP/1.1" 200 5848
[2020-03-31 11:16:14,146] [INFO] "GET /admin/jsi18n/ HTTP/1.1" 200 7722
[2020-03-31 11:16:40,791] [INFO] E:\Data Processing Evaluation Tool\mysite\QCtool\Item\VD.py changed, reloading.
[2020-03-31 11:16:41,683] [INFO] Watching for file changes with StatReloader
[2020-03-31 11:16:45,238] [INFO] "GET /admin/QCtool/ionratioframe/ HTTP/1.1" 200 5643
[2020-03-31 11:16:45,266] [INFO] "GET /admin/jsi18n/ HTTP/1.1" 200 7722
[2020-03-31 11:16:47,568] [INFO] "GET /admin/QCtool/ionratioframe/2/change/ HTTP/1.1" 200 5282
[2020-03-31 11:16:47,583] [INFO] "GET /admin/jsi18n/ HTTP/1.1" 200 7722
[2020-03-31 11:16:49,130] [INFO] "GET /admin/QCtool/ionratioframe/ HTTP/1.1" 200 5643
[2020-03-31 11:17:09,948] [ERROR] Internal Server Error: /
Traceback (most recent call last):
  File "C:\Users\lihua\AppData\Local\Programs\Python\Python37\lib\site-packages\django\core\handlers\exception.py", line 34, in inner
    response = get_response(request)
  File "C:\Users\lihua\AppData\Local\Programs\Python\Python37\lib\site-packages\django\core\handlers\base.py", line 115, in _get_response
    response = self.process_exception_by_middleware(e, request)
  File "C:\Users\lihua\AppData\Local\Programs\Python\Python37\lib\site-packages\django\core\handlers\base.py", line 113, in _get_response
    response = wrapped_callback(request, *callback_args, **callback_kwargs)
  File "E:\Data Processing Evaluation Tool\mysite\QCtool\views.py", line 29, in file_upload
    raise e
  File "E:\Data Processing Evaluation Tool\mysite\QCtool\views.py", line 27, in file_upload
    content = handle_uploaded_file(file, item, num, types)
  File "E:\Data Processing Evaluation Tool\mysite\QCtool\Item\handle.py", line 23, in handle_uploaded_file
    return vd.output()
  File "E:\Data Processing Evaluation Tool\mysite\QCtool\Item\VD.py", line 614, in output
    output["d2_Ion_Ratio"] = self.get_Ion_Ratio(dic[self.D2], self.D2_LLMI, self.instrument_prefix + self.instrument_num, "VD")
  File "E:\Data Processing Evaluation Tool\mysite\QCtool\main.py", line 613, in get_Ion_Ratio
    IonRatio = IonRatioFrame.objects.filter(instrument=instrument, item=item)[0]
  File "C:\Users\lihua\AppData\Local\Programs\Python\Python37\lib\site-packages\django\db\models\query.py", line 309, in __getitem__
    return qs._result_cache[0]
IndexError: list index out of range
[2020-03-31 11:17:10,080] [ERROR] "POST / HTTP/1.1" 500 132118
[2020-03-31 11:17:33,924] [INFO] "GET /admin/QCtool/ionratioframe/2/change/ HTTP/1.1" 200 5282
[2020-03-31 11:17:33,942] [INFO] "GET /admin/jsi18n/ HTTP/1.1" 200 7722
[2020-03-31 11:17:38,535] [INFO] "POST /admin/QCtool/ionratioframe/2/change/ HTTP/1.1" 302 0
[2020-03-31 11:17:38,572] [INFO] "GET /admin/QCtool/ionratioframe/ HTTP/1.1" 200 5868
[2020-03-31 11:17:38,588] [INFO] "GET /admin/jsi18n/ HTTP/1.1" 200 7722
[2020-03-31 11:17:39,709] [INFO] "GET /admin/QCtool/ionratioframe/1/change/ HTTP/1.1" 200 5282
[2020-03-31 11:17:39,725] [INFO] "GET /admin/jsi18n/ HTTP/1.1" 200 7722
[2020-03-31 11:17:44,652] [INFO] "POST /admin/QCtool/ionratioframe/1/change/ HTTP/1.1" 302 0
[2020-03-31 11:17:44,720] [INFO] "GET /admin/QCtool/ionratioframe/ HTTP/1.1" 200 5884
[2020-03-31 11:17:44,742] [INFO] "GET /admin/jsi18n/ HTTP/1.1" 200 7722
[2020-03-31 11:17:48,038] [INFO] "GET / HTTP/1.1" 200 3290
[2020-03-31 11:18:04,451] [ERROR] Internal Server Error: /
Traceback (most recent call last):
  File "C:\Users\lihua\AppData\Local\Programs\Python\Python37\lib\site-packages\django\core\handlers\exception.py", line 34, in inner
    response = get_response(request)
  File "C:\Users\lihua\AppData\Local\Programs\Python\Python37\lib\site-packages\django\core\handlers\base.py", line 115, in _get_response
    response = self.process_exception_by_middleware(e, request)
  File "C:\Users\lihua\AppData\Local\Programs\Python\Python37\lib\site-packages\django\core\handlers\base.py", line 113, in _get_response
    response = wrapped_callback(request, *callback_args, **callback_kwargs)
  File "E:\Data Processing Evaluation Tool\mysite\QCtool\views.py", line 29, in file_upload
    raise e
  File "E:\Data Processing Evaluation Tool\mysite\QCtool\views.py", line 27, in file_upload
    content = handle_uploaded_file(file, item, num, types)
  File "E:\Data Processing Evaluation Tool\mysite\QCtool\Item\handle.py", line 23, in handle_uploaded_file
    return vd.output()
  File "E:\Data Processing Evaluation Tool\mysite\QCtool\Item\VD.py", line 614, in output
    output["d2_Ion_Ratio"] = self.get_Ion_Ratio(dic[self.D2], self.D2_LLMI, self.instrument_prefix + self.instrument_num, "VD")
  File "E:\Data Processing Evaluation Tool\mysite\QCtool\main.py", line 630, in get_Ion_Ratio
    if (sampleIonRatio / IonRatio - 1) < 0.2:
TypeError: unsupported operand type(s) for /: 'float' and 'IonRatioFrame'
[2020-03-31 11:18:04,577] [ERROR] "POST / HTTP/1.1" 500 129455
[2020-03-31 11:18:43,608] [INFO] E:\Data Processing Evaluation Tool\mysite\QCtool\main.py changed, reloading.
[2020-03-31 11:18:44,527] [INFO] Watching for file changes with StatReloader
[2020-03-31 11:19:29,554] [INFO] E:\Data Processing Evaluation Tool\mysite\QCtool\main.py changed, reloading.
[2020-03-31 11:19:30,413] [INFO] Watching for file changes with StatReloader
[2020-03-31 11:19:32,399] [ERROR] Internal Server Error: /
Traceback (most recent call last):
  File "C:\Users\lihua\AppData\Local\Programs\Python\Python37\lib\site-packages\django\core\handlers\exception.py", line 34, in inner
    response = get_response(request)
  File "C:\Users\lihua\AppData\Local\Programs\Python\Python37\lib\site-packages\django\core\handlers\base.py", line 115, in _get_response
    response = self.process_exception_by_middleware(e, request)
  File "C:\Users\lihua\AppData\Local\Programs\Python\Python37\lib\site-packages\django\core\handlers\base.py", line 113, in _get_response
    response = wrapped_callback(request, *callback_args, **callback_kwargs)
  File "E:\Data Processing Evaluation Tool\mysite\QCtool\views.py", line 29, in file_upload
    raise e
  File "E:\Data Processing Evaluation Tool\mysite\QCtool\views.py", line 27, in file_upload
    content = handle_uploaded_file(file, item, num, types)
  File "E:\Data Processing Evaluation Tool\mysite\QCtool\Item\handle.py", line 23, in handle_uploaded_file
    return vd.output()
  File "E:\Data Processing Evaluation Tool\mysite\QCtool\Item\VD.py", line 617, in output
    raise
RuntimeError: No active exception to reraise
[2020-03-31 11:19:32,514] [ERROR] "POST / HTTP/1.1" 500 114700
[2020-03-31 11:24:52,203] [INFO] E:\Data Processing Evaluation Tool\mysite\QCtool\main.py changed, reloading.
[2020-03-31 11:24:53,064] [INFO] Watching for file changes with StatReloader
[2020-03-31 11:26:23,890] [INFO] E:\Data Processing Evaluation Tool\mysite\QCtool\main.py changed, reloading.
[2020-03-31 11:26:24,772] [INFO] Watching for file changes with StatReloader
[2020-03-31 11:32:26,279] [INFO] E:\Data Processing Evaluation Tool\mysite\QCtool\Item\VD.py changed, reloading.
[2020-03-31 11:32:27,164] [INFO] Watching for file changes with StatReloader
[2020-03-31 11:32:28,813] [ERROR] Internal Server Error: /
Traceback (most recent call last):
  File "C:\Users\lihua\AppData\Local\Programs\Python\Python37\lib\site-packages\django\core\handlers\exception.py", line 34, in inner
    response = get_response(request)
  File "C:\Users\lihua\AppData\Local\Programs\Python\Python37\lib\site-packages\django\core\handlers\base.py", line 115, in _get_response
    response = self.process_exception_by_middleware(e, request)
  File "C:\Users\lihua\AppData\Local\Programs\Python\Python37\lib\site-packages\django\core\handlers\base.py", line 113, in _get_response
    response = wrapped_callback(request, *callback_args, **callback_kwargs)
  File "E:\Data Processing Evaluation Tool\mysite\QCtool\views.py", line 29, in file_upload
    raise e
  File "E:\Data Processing Evaluation Tool\mysite\QCtool\views.py", line 27, in file_upload
    content = handle_uploaded_file(file, item, num, types)
  File "E:\Data Processing Evaluation Tool\mysite\QCtool\Item\handle.py", line 23, in handle_uploaded_file
    return vd.output()
  File "E:\Data Processing Evaluation Tool\mysite\QCtool\Item\VD.py", line 614, in output
    output["d2_Ion_Ratio"] = self.get_Ion_Ratio(dic[self.D2], self.D2_LLMI, self.instrument_prefix + self.instrument_num, "VD")
  File "E:\Data Processing Evaluation Tool\mysite\QCtool\main.py", line 631, in get_Ion_Ratio
    RatioPassNum += 1
UnboundLocalError: local variable 'RatioPassNum' referenced before assignment
[2020-03-31 11:32:28,942] [ERROR] "POST / HTTP/1.1" 500 129322
[2020-03-31 11:32:57,796] [INFO] E:\Data Processing Evaluation Tool\mysite\QCtool\main.py changed, reloading.
[2020-03-31 11:32:58,672] [INFO] Watching for file changes with StatReloader
[2020-03-31 11:32:59,691] [INFO] 提交数据:YZ06-20200317.csv
[2020-03-31 11:32:59,761] [INFO] "POST / HTTP/1.1" 200 34466
[2020-03-31 11:33:40,043] [INFO] 提交数据:YZ06-20200317.csv
[2020-03-31 11:33:40,083] [INFO] "POST / HTTP/1.1" 200 34471
[2020-03-31 11:34:25,383] [INFO] 提交数据:YZ06-20200317.csv
[2020-03-31 11:34:25,404] [INFO] "POST / HTTP/1.1" 200 34471
[2020-03-31 11:34:51,557] [INFO] E:\Data Processing Evaluation Tool\mysite\QCtool\main.py changed, reloading.
[2020-03-31 11:34:52,450] [INFO] Watching for file changes with StatReloader
[2020-03-31 11:34:53,663] [INFO] 提交数据:YZ06-20200317.csv
[2020-03-31 11:34:53,741] [INFO] "POST / HTTP/1.1" 200 34480
[2020-03-31 11:35:27,183] [INFO] 提交数据:YZ06-20200317.csv
[2020-03-31 11:35:27,222] [INFO] "POST / HTTP/1.1" 200 34452
[2020-03-31 11:36:28,658] [INFO] 提交数据:YZ06-20200317.csv
[2020-03-31 11:36:28,678] [INFO] "POST / HTTP/1.1" 200 34452
[2020-03-31 11:37:31,613] [INFO] 提交数据:YZ06-20200317.csv
[2020-03-31 11:37:31,632] [INFO] "POST / HTTP/1.1" 200 34463
[2020-03-31 11:38:01,210] [INFO] 提交数据:YZ06-20200317.csv
[2020-03-31 11:38:01,237] [INFO] "POST / HTTP/1.1" 200 34468
[2020-03-31 11:38:58,752] [INFO] 提交数据:YZ06-20200317.csv
[2020-03-31 11:38:58,792] [INFO] "POST / HTTP/1.1" 200 34650
[2020-03-31 11:40:35,990] [INFO] 提交数据:YZ06-20200317.csv
[2020-03-31 11:40:36,269] [ERROR] Internal Server Error: /
Traceback (most recent call last):
  File "C:\Users\lihua\AppData\Local\Programs\Python\Python37\lib\site-packages\django\template\base.py", line 470, in parse
    compile_func = self.tags[command]
KeyError: 'end'

During handling of the above exception, another exception occurred:

Traceback (most recent call last):
  File "C:\Users\lihua\AppData\Local\Programs\Python\Python37\lib\site-packages\django\core\handlers\exception.py", line 34, in inner
    response = get_response(request)
  File "C:\Users\lihua\AppData\Local\Programs\Python\Python37\lib\site-packages\django\core\handlers\base.py", line 115, in _get_response
    response = self.process_exception_by_middleware(e, request)
  File "C:\Users\lihua\AppData\Local\Programs\Python\Python37\lib\site-packages\django\core\handlers\base.py", line 113, in _get_response
    response = wrapped_callback(request, *callback_args, **callback_kwargs)
  File "E:\Data Processing Evaluation Tool\mysite\QCtool\views.py", line 48, in file_upload
    return render(request, "VD.html", content)
  File "C:\Users\lihua\AppData\Local\Programs\Python\Python37\lib\site-packages\django\shortcuts.py", line 36, in render
    content = loader.render_to_string(template_name, context, request, using=using)
  File "C:\Users\lihua\AppData\Local\Programs\Python\Python37\lib\site-packages\django\template\loader.py", line 61, in render_to_string
    template = get_template(template_name, using=using)
  File "C:\Users\lihua\AppData\Local\Programs\Python\Python37\lib\site-packages\django\template\loader.py", line 15, in get_template
    return engine.get_template(template_name)
  File "C:\Users\lihua\AppData\Local\Programs\Python\Python37\lib\site-packages\django\template\backends\django.py", line 34, in get_template
    return Template(self.engine.get_template(template_name), self)
  File "C:\Users\lihua\AppData\Local\Programs\Python\Python37\lib\site-packages\django\template\engine.py", line 143, in get_template
    template, origin = self.find_template(template_name)
  File "C:\Users\lihua\AppData\Local\Programs\Python\Python37\lib\site-packages\django\template\engine.py", line 125, in find_template
    template = loader.get_template(name, skip=skip)
  File "C:\Users\lihua\AppData\Local\Programs\Python\Python37\lib\site-packages\django\template\loaders\base.py", line 30, in get_template
    contents, origin, origin.template_name, self.engine,
  File "C:\Users\lihua\AppData\Local\Programs\Python\Python37\lib\site-packages\django\template\base.py", line 156, in __init__
    self.nodelist = self.compile_nodelist()
  File "C:\Users\lihua\AppData\Local\Programs\Python\Python37\lib\site-packages\django\template\base.py", line 194, in compile_nodelist
    return parser.parse()
  File "C:\Users\lihua\AppData\Local\Programs\Python\Python37\lib\site-packages\django\template\base.py", line 478, in parse
    raise self.error(token, e)
  File "C:\Users\lihua\AppData\Local\Programs\Python\Python37\lib\site-packages\django\template\base.py", line 476, in parse
    compiled_result = compile_func(self, token)
  File "C:\Users\lihua\AppData\Local\Programs\Python\Python37\lib\site-packages\django\template\loader_tags.py", line 266, in do_extends
    nodelist = parser.parse()
  File "C:\Users\lihua\AppData\Local\Programs\Python\Python37\lib\site-packages\django\template\base.py", line 478, in parse
    raise self.error(token, e)
  File "C:\Users\lihua\AppData\Local\Programs\Python\Python37\lib\site-packages\django\template\base.py", line 476, in parse
    compiled_result = compile_func(self, token)
  File "C:\Users\lihua\AppData\Local\Programs\Python\Python37\lib\site-packages\django\template\loader_tags.py", line 209, in do_block
    nodelist = parser.parse(('endblock',))
  File "C:\Users\lihua\AppData\Local\Programs\Python\Python37\lib\site-packages\django\template\base.py", line 478, in parse
    raise self.error(token, e)
  File "C:\Users\lihua\AppData\Local\Programs\Python\Python37\lib\site-packages\django\template\base.py", line 476, in parse
    compiled_result = compile_func(self, token)
  File "C:\Users\lihua\AppData\Local\Programs\Python\Python37\lib\site-packages\django\template\defaulttags.py", line 811, in do_for
    nodelist_loop = parser.parse(('empty', 'endfor',))
  File "C:\Users\lihua\AppData\Local\Programs\Python\Python37\lib\site-packages\django\template\base.py", line 472, in parse
    self.invalid_block_tag(token, command, parse_until)
  File "C:\Users\lihua\AppData\Local\Programs\Python\Python37\lib\site-packages\django\template\base.py", line 528, in invalid_block_tag
    get_text_list(["'%s'" % p for p in parse_until], 'or'),
django.template.exceptions.TemplateSyntaxError: Invalid block tag on line 433: 'end', expected 'empty' or 'endfor'. Did you forget to register or load this tag?
[2020-03-31 11:40:36,354] [ERROR] "POST / HTTP/1.1" 500 227392
[2020-03-31 11:40:46,032] [INFO] 提交数据:YZ06-20200317.csv
[2020-03-31 11:40:46,068] [INFO] "POST / HTTP/1.1" 200 34738
[2020-03-31 11:41:40,429] [INFO] E:\Data Processing Evaluation Tool\mysite\QCtool\Item\VD.py changed, reloading.
[2020-03-31 11:41:41,326] [INFO] Watching for file changes with StatReloader
[2020-03-31 11:41:42,636] [ERROR] Internal Server Error: /
Traceback (most recent call last):
  File "C:\Users\lihua\AppData\Local\Programs\Python\Python37\lib\site-packages\django\core\handlers\exception.py", line 34, in inner
    response = get_response(request)
  File "C:\Users\lihua\AppData\Local\Programs\Python\Python37\lib\site-packages\django\core\handlers\base.py", line 115, in _get_response
    response = self.process_exception_by_middleware(e, request)
  File "C:\Users\lihua\AppData\Local\Programs\Python\Python37\lib\site-packages\django\core\handlers\base.py", line 113, in _get_response
    response = wrapped_callback(request, *callback_args, **callback_kwargs)
  File "E:\Data Processing Evaluation Tool\mysite\QCtool\views.py", line 29, in file_upload
    raise e
  File "E:\Data Processing Evaluation Tool\mysite\QCtool\views.py", line 27, in file_upload
    content = handle_uploaded_file(file, item, num, types)
  File "E:\Data Processing Evaluation Tool\mysite\QCtool\Item\handle.py", line 23, in handle_uploaded_file
    return vd.output()
  File "E:\Data Processing Evaluation Tool\mysite\QCtool\Item\VD.py", line 617, in output
    raise
RuntimeError: No active exception to reraise
[2020-03-31 11:41:42,748] [ERROR] "POST / HTTP/1.1" 500 114808
[2020-03-31 11:43:08,210] [INFO] E:\Data Processing Evaluation Tool\mysite\QCtool\Item\VD.py changed, reloading.
[2020-03-31 11:43:09,064] [INFO] Watching for file changes with StatReloader
[2020-03-31 11:43:10,210] [INFO] 提交数据:YZ06-20200317.csv
[2020-03-31 11:43:10,267] [INFO] "POST / HTTP/1.1" 200 34965
[2020-03-31 11:43:42,349] [INFO] 提交数据:YZ06-20200317.csv
[2020-03-31 11:43:42,386] [INFO] "POST / HTTP/1.1" 200 34965
[2020-03-31 11:45:29,212] [INFO] "GET / HTTP/1.1" 200 3290
[2020-03-31 11:45:42,220] [INFO] 提交数据:YZ07-20200317.csv
[2020-03-31 11:45:42,262] [INFO] "POST / HTTP/1.1" 200 36926
[2020-03-31 11:46:55,193] [INFO] "GET /admin/QCtool/ionratioframe/2/change/ HTTP/1.1" 200 5290
[2020-03-31 11:46:55,209] [INFO] "GET /admin/jsi18n/ HTTP/1.1" 200 7722
[2020-03-31 11:46:58,612] [INFO] "POST /admin/QCtool/ionratioframe/2/change/ HTTP/1.1" 302 0
[2020-03-31 11:46:58,666] [INFO] "GET /admin/QCtool/ionratioframe/ HTTP/1.1" 200 5884
[2020-03-31 11:46:58,681] [INFO] "GET /admin/jsi18n/ HTTP/1.1" 200 7722
[2020-03-31 11:47:47,529] [INFO] E:\Data Processing Evaluation Tool\mysite\QCtool\Item\VD.py changed, reloading.
[2020-03-31 11:47:48,570] [INFO] Watching for file changes with StatReloader
[2020-03-31 11:47:51,371] [ERROR] Internal Server Error: /
Traceback (most recent call last):
  File "C:\Users\lihua\AppData\Local\Programs\Python\Python37\lib\site-packages\django\core\handlers\exception.py", line 34, in inner
    response = get_response(request)
  File "C:\Users\lihua\AppData\Local\Programs\Python\Python37\lib\site-packages\django\core\handlers\base.py", line 115, in _get_response
    response = self.process_exception_by_middleware(e, request)
  File "C:\Users\lihua\AppData\Local\Programs\Python\Python37\lib\site-packages\django\core\handlers\base.py", line 113, in _get_response
    response = wrapped_callback(request, *callback_args, **callback_kwargs)
  File "E:\Data Processing Evaluation Tool\mysite\QCtool\views.py", line 29, in file_upload
    raise e
  File "E:\Data Processing Evaluation Tool\mysite\QCtool\views.py", line 27, in file_upload
    content = handle_uploaded_file(file, item, num, types)
  File "E:\Data Processing Evaluation Tool\mysite\QCtool\Item\handle.py", line 23, in handle_uploaded_file
    return vd.output()
  File "E:\Data Processing Evaluation Tool\mysite\QCtool\Item\VD.py", line 616, in output
    raise
RuntimeError: No active exception to reraise
[2020-03-31 11:47:51,491] [ERROR] "POST / HTTP/1.1" 500 114706
[2020-03-31 11:48:53,931] [INFO] E:\Data Processing Evaluation Tool\mysite\QCtool\main.py changed, reloading.
[2020-03-31 11:48:56,574] [INFO] Watching for file changes with StatReloader
[2020-03-31 11:54:19,814] [INFO] E:\Data Processing Evaluation Tool\mysite\QCtool\Item\VD.py changed, reloading.
[2020-03-31 11:54:20,809] [INFO] Watching for file changes with StatReloader
[2020-03-31 11:54:23,770] [INFO] "GET /admin/QCtool/ionratioframe/1/change/ HTTP/1.1" 200 5290
[2020-03-31 11:54:23,788] [INFO] "GET /admin/jsi18n/ HTTP/1.1" 200 7722
[2020-03-31 11:54:27,458] [INFO] "POST /admin/QCtool/ionratioframe/1/change/ HTTP/1.1" 302 0
[2020-03-31 11:54:27,497] [INFO] "GET /admin/QCtool/ionratioframe/ HTTP/1.1" 200 5940
[2020-03-31 11:54:27,513] [INFO] "GET /admin/jsi18n/ HTTP/1.1" 200 7722
[2020-03-31 11:54:28,493] [INFO] "GET /admin/QCtool/ionratioframe/2/change/ HTTP/1.1" 200 5290
[2020-03-31 11:54:28,509] [INFO] "GET /admin/jsi18n/ HTTP/1.1" 200 7722
[2020-03-31 11:54:31,058] [INFO] "POST /admin/QCtool/ionratioframe/2/change/ HTTP/1.1" 302 0
[2020-03-31 11:54:31,102] [INFO] "GET /admin/QCtool/ionratioframe/ HTTP/1.1" 200 5884
[2020-03-31 11:54:31,115] [INFO] "GET /admin/jsi18n/ HTTP/1.1" 200 7722
[2020-03-31 11:54:32,248] [INFO] "GET /admin/QCtool/ionratioframe/add/ HTTP/1.1" 200 5023
[2020-03-31 11:54:32,261] [INFO] "GET /admin/jsi18n/ HTTP/1.1" 200 7722
[2020-03-31 11:54:46,866] [INFO] "POST /admin/QCtool/ionratioframe/add/ HTTP/1.1" 302 0
[2020-03-31 11:54:46,933] [INFO] "GET /admin/QCtool/ionratioframe/ HTTP/1.1" 200 6237
[2020-03-31 11:54:46,949] [INFO] "GET /admin/jsi18n/ HTTP/1.1" 200 7722
[2020-03-31 11:54:48,538] [INFO] "GET /admin/QCtool/ionratioframe/2/change/ HTTP/1.1" 200 5290
[2020-03-31 11:54:48,554] [INFO] "GET /admin/jsi18n/ HTTP/1.1" 200 7722
[2020-03-31 11:54:53,073] [INFO] "GET /admin/QCtool/ionratioframe/ HTTP/1.1" 200 6028
[2020-03-31 11:54:53,086] [INFO] "GET /admin/jsi18n/ HTTP/1.1" 200 7722
[2020-03-31 11:54:54,392] [INFO] "GET /admin/QCtool/ionratioframe/add/ HTTP/1.1" 200 5023
[2020-03-31 11:54:54,408] [INFO] "GET /admin/jsi18n/ HTTP/1.1" 200 7722
[2020-03-31 11:55:03,149] [INFO] "POST /admin/QCtool/ionratioframe/add/ HTTP/1.1" 302 0
[2020-03-31 11:55:03,206] [INFO] "GET /admin/QCtool/ionratioframe/ HTTP/1.1" 200 6534
[2020-03-31 11:55:03,221] [INFO] "GET /admin/jsi18n/ HTTP/1.1" 200 7722
[2020-03-31 11:55:04,987] [INFO] "GET /admin/QCtool/ionratioframe/?o=1 HTTP/1.1" 200 6725
[2020-03-31 11:55:05,002] [INFO] "GET /admin/jsi18n/ HTTP/1.1" 200 7722
[2020-03-31 11:55:05,026] [INFO] "GET /static/admin/img/sorting-icons.svg HTTP/1.1" 200 1097
[2020-03-31 11:55:17,540] [ERROR] Internal Server Error: /
Traceback (most recent call last):
  File "C:\Users\lihua\AppData\Local\Programs\Python\Python37\lib\site-packages\django\core\handlers\exception.py", line 34, in inner
    response = get_response(request)
  File "C:\Users\lihua\AppData\Local\Programs\Python\Python37\lib\site-packages\django\core\handlers\base.py", line 115, in _get_response
    response = self.process_exception_by_middleware(e, request)
  File "C:\Users\lihua\AppData\Local\Programs\Python\Python37\lib\site-packages\django\core\handlers\base.py", line 113, in _get_response
    response = wrapped_callback(request, *callback_args, **callback_kwargs)
  File "E:\Data Processing Evaluation Tool\mysite\QCtool\views.py", line 29, in file_upload
    raise e
  File "E:\Data Processing Evaluation Tool\mysite\QCtool\views.py", line 27, in file_upload
    content = handle_uploaded_file(file, item, num, types)
  File "E:\Data Processing Evaluation Tool\mysite\QCtool\Item\handle.py", line 23, in handle_uploaded_file
    return vd.output()
  File "E:\Data Processing Evaluation Tool\mysite\QCtool\Item\VD.py", line 616, in output
    raise
RuntimeError: No active exception to reraise
[2020-03-31 11:55:17,655] [ERROR] "POST / HTTP/1.1" 500 114679
[2020-03-31 11:58:34,925] [INFO] E:\Data Processing Evaluation Tool\mysite\QCtool\main.py changed, reloading.
[2020-03-31 11:58:35,901] [INFO] Watching for file changes with StatReloader
[2020-03-31 11:58:40,871] [INFO] E:\Data Processing Evaluation Tool\mysite\QCtool\Item\VD.py changed, reloading.
[2020-03-31 11:58:41,708] [INFO] Watching for file changes with StatReloader
[2020-03-31 11:58:43,159] [INFO] 提交数据:YZ07-20200317.csv
[2020-03-31 11:58:43,242] [INFO] "POST / HTTP/1.1" 200 47061
[2020-03-31 11:59:09,811] [INFO] "GET /admin/QCtool/ionratioframe/2/change/?_changelist_filters=o%3D1 HTTP/1.1" 200 5368
[2020-03-31 11:59:09,827] [INFO] "GET /admin/jsi18n/ HTTP/1.1" 200 7722
[2020-03-31 11:59:12,656] [INFO] "POST /admin/QCtool/ionratioframe/2/change/?_changelist_filters=o%3D1 HTTP/1.1" 302 0
[2020-03-31 11:59:12,710] [INFO] "GET /admin/QCtool/ionratioframe/?o=1 HTTP/1.1" 200 6934
[2020-03-31 11:59:12,725] [INFO] "GET /admin/jsi18n/ HTTP/1.1" 200 7722
[2020-03-31 11:59:13,933] [INFO] "GET /admin/QCtool/ionratioframe/4/change/?_changelist_filters=o%3D1 HTTP/1.1" 200 5368
[2020-03-31 11:59:13,949] [INFO] "GET /admin/jsi18n/ HTTP/1.1" 200 7722
[2020-03-31 11:59:37,829] [INFO] "POST /admin/QCtool/ionratioframe/4/change/?_changelist_filters=o%3D1 HTTP/1.1" 302 0
[2020-03-31 11:59:37,870] [INFO] "GET /admin/QCtool/ionratioframe/?o=1 HTTP/1.1" 200 6934
[2020-03-31 11:59:37,886] [INFO] "GET /admin/jsi18n/ HTTP/1.1" 200 7722
[2020-03-31 11:59:43,294] [INFO] 提交数据:YZ07-20200317.csv
[2020-03-31 11:59:43,325] [INFO] "POST / HTTP/1.1" 200 45311
[2020-03-31 12:01:09,871] [INFO] 提交数据:YZ07-20200317.csv
[2020-03-31 12:01:09,908] [INFO] "POST / HTTP/1.1" 200 45429
[2020-03-31 12:01:26,445] [INFO] 提交数据:YZ07-20200317.csv
[2020-03-31 12:01:26,489] [INFO] "POST / HTTP/1.1" 200 45435
[2020-03-31 12:02:03,267] [INFO] "GET /admin/QCtool/ionratioframe/4/change/?_changelist_filters=o%3D1 HTTP/1.1" 200 5368
[2020-03-31 12:02:03,425] [INFO] "GET /admin/jsi18n/ HTTP/1.1" 200 7722
[2020-03-31 12:02:06,991] [INFO] "POST /admin/QCtool/ionratioframe/4/change/?_changelist_filters=o%3D1 HTTP/1.1" 302 0
[2020-03-31 12:02:07,143] [INFO] "GET /admin/QCtool/ionratioframe/?o=1 HTTP/1.1" 200 6934
[2020-03-31 12:02:07,175] [INFO] "GET /admin/jsi18n/ HTTP/1.1" 200 7722
[2020-03-31 12:02:11,936] [INFO] 提交数据:YZ07-20200317.csv
[2020-03-31 12:02:11,983] [INFO] "POST / HTTP/1.1" 200 37703
[2020-03-31 12:03:42,650] [INFO] "GET / HTTP/1.1" 200 3290
[2020-03-31 12:04:01,595] [INFO] 提交数据:YZ07-20200329-质量评估工具.csv
[2020-03-31 12:04:01,649] [INFO] "POST / HTTP/1.1" 200 42875
[2020-03-31 12:04:20,398] [INFO] E:\Data Processing Evaluation Tool\mysite\QCtool\main.py changed, reloading.
[2020-03-31 12:04:22,959] [INFO] Watching for file changes with StatReloader
[2020-03-31 12:04:29,720] [INFO] "GET / HTTP/1.1" 200 3290
[2020-03-31 12:04:45,274] [ERROR] Internal Server Error: /
Traceback (most recent call last):
  File "C:\Users\lihua\AppData\Local\Programs\Python\Python37\lib\site-packages\django\core\handlers\exception.py", line 34, in inner
    response = get_response(request)
  File "C:\Users\lihua\AppData\Local\Programs\Python\Python37\lib\site-packages\django\core\handlers\base.py", line 115, in _get_response
    response = self.process_exception_by_middleware(e, request)
  File "C:\Users\lihua\AppData\Local\Programs\Python\Python37\lib\site-packages\django\core\handlers\base.py", line 113, in _get_response
    response = wrapped_callback(request, *callback_args, **callback_kwargs)
  File "E:\Data Processing Evaluation Tool\mysite\QCtool\views.py", line 29, in file_upload
    raise e
  File "E:\Data Processing Evaluation Tool\mysite\QCtool\views.py", line 27, in file_upload
    content = handle_uploaded_file(file, item, num, types)
  File "E:\Data Processing Evaluation Tool\mysite\QCtool\Item\handle.py", line 22, in handle_uploaded_file
    vd = VD(f=f, instrument_num=instrument_num, instrument_type=instrument_type)
  File "E:\Data Processing Evaluation Tool\mysite\QCtool\Item\VD.py", line 84, in __init__
    super().__init__(self.NAME,
AttributeError: 'VD' object has no attribute 'NAME'
[2020-03-31 12:04:45,470] [ERROR] "POST / HTTP/1.1" 500 82338
[2020-03-31 12:04:50,195] [INFO] 提交数据:YZ07-20200329-质量评估工具.csv
[2020-03-31 12:04:50,369] [INFO] "POST / HTTP/1.1" 200 37981
[2020-03-31 12:06:00,189] [INFO] "GET / HTTP/1.1" 200 3290
[2020-03-31 12:06:09,116] [INFO] 提交数据:YZ06-20200307-质量评估工具.csv
[2020-03-31 12:06:09,136] [INFO] "POST / HTTP/1.1" 200 33560
[2020-03-31 12:06:18,860] [INFO] "GET / HTTP/1.1" 200 3290
[2020-03-31 12:06:52,188] [INFO] "GET /admin/logout/ HTTP/1.1" 200 1191
[2020-03-31 12:40:17,885] [INFO] Watching for file changes with StatReloader
[2020-03-31 12:40:22,051] [INFO] "GET / HTTP/1.1" 200 3290
[2020-03-31 12:40:22,219] [WARNING] Not Found: /favicon.ico
[2020-03-31 12:40:22,219] [WARNING] "GET /favicon.ico HTTP/1.1" 404 2323
[2020-03-31 12:40:51,026] [ERROR] Internal Server Error: /
Traceback (most recent call last):
  File "C:\Users\lihua\AppData\Local\Programs\Python\Python37\lib\site-packages\django\core\handlers\exception.py", line 34, in inner
    response = get_response(request)
  File "C:\Users\lihua\AppData\Local\Programs\Python\Python37\lib\site-packages\django\core\handlers\base.py", line 115, in _get_response
    response = self.process_exception_by_middleware(e, request)
  File "C:\Users\lihua\AppData\Local\Programs\Python\Python37\lib\site-packages\django\core\handlers\base.py", line 113, in _get_response
    response = wrapped_callback(request, *callback_args, **callback_kwargs)
  File "E:\Data Processing Evaluation Tool\mysite\QCtool\views.py", line 29, in file_upload
    raise e
  File "E:\Data Processing Evaluation Tool\mysite\QCtool\views.py", line 27, in file_upload
    content = handle_uploaded_file(file, item, num, types)
  File "E:\Data Processing Evaluation Tool\mysite\QCtool\Item\handle.py", line 23, in handle_uploaded_file
    return vd.output()
  File "E:\Data Processing Evaluation Tool\mysite\QCtool\Item\VD.py", line 614, in output
    output["d2_Ion_Ratio"] = self.get_Ion_Ratio(dic[self.D2], self.D2_LLMI, self.instrument_prefix + self.instrument_num, self.D2)
  File "E:\Data Processing Evaluation Tool\mysite\QCtool\main.py", line 613, in get_Ion_Ratio
    IonRatio = IonRatioFrame.objects.filter(instrument=instrument, item=item)[0]
  File "C:\Users\lihua\AppData\Local\Programs\Python\Python37\lib\site-packages\django\db\models\query.py", line 309, in __getitem__
    return qs._result_cache[0]
IndexError: list index out of range
[2020-03-31 12:40:51,166] [ERROR] "POST / HTTP/1.1" 500 129691
[2020-03-31 12:42:47,674] [INFO] E:\Data Processing Evaluation Tool\mysite\QCtool\main.py changed, reloading.
[2020-03-31 12:42:52,156] [INFO] Watching for file changes with StatReloader
[2020-03-31 12:42:55,756] [INFO] E:\Data Processing Evaluation Tool\mysite\QCtool\main.py changed, reloading.
[2020-03-31 12:42:56,777] [INFO] Watching for file changes with StatReloader
[2020-03-31 12:43:25,376] [INFO] 提交数据:YZ02-20200330-S1-质量评估工具.docx
[2020-03-31 12:43:25,441] [INFO] "POST / HTTP/1.1" 200 36841
[2020-03-31 12:44:32,566] [INFO] "GET / HTTP/1.1" 200 3290
[2020-03-31 12:44:45,253] [INFO] 提交数据:YZ21-20200330-质量评估工具.txt
[2020-03-31 12:44:45,272] [INFO] "POST / HTTP/1.1" 200 34355
[2020-03-31 12:45:01,504] [INFO] "GET / HTTP/1.1" 200 3290
[2020-03-31 12:45:12,329] [INFO] 提交数据:YZ06-20200307-质量评估工具.csv
[2020-03-31 12:45:12,359] [INFO] "POST / HTTP/1.1" 200 33560
[2020-03-31 12:45:19,006] [INFO] "GET / HTTP/1.1" 200 3290
[2020-03-31 15:53:07,648] [INFO] Watching for file changes with StatReloader
[2020-03-31 15:53:13,067] [INFO] "GET / HTTP/1.1" 200 3290
[2020-03-31 15:53:13,209] [WARNING] Not Found: /favicon.ico
[2020-03-31 15:53:13,210] [WARNING] "GET /favicon.ico HTTP/1.1" 404 2323
[2020-03-31 15:53:21,750] [ERROR] Internal Server Error: /
Traceback (most recent call last):
  File "C:\Users\lihua\AppData\Local\Programs\Python\Python37\lib\site-packages\django\core\handlers\exception.py", line 34, in inner
    response = get_response(request)
  File "C:\Users\lihua\AppData\Local\Programs\Python\Python37\lib\site-packages\django\core\handlers\base.py", line 115, in _get_response
    response = self.process_exception_by_middleware(e, request)
  File "C:\Users\lihua\AppData\Local\Programs\Python\Python37\lib\site-packages\django\core\handlers\base.py", line 113, in _get_response
    response = wrapped_callback(request, *callback_args, **callback_kwargs)
  File "E:\Data Processing Evaluation Tool\mysite\QCtool\views.py", line 29, in file_upload
    raise e
  File "E:\Data Processing Evaluation Tool\mysite\QCtool\views.py", line 27, in file_upload
    content = handle_uploaded_file(file, item, num, types)
  File "E:\Data Processing Evaluation Tool\mysite\QCtool\Item\handle.py", line 10, in handle_uploaded_file
    pmns = PMNs(f=f, instrument_num=instrument_num, instrument_type=instrument_type)
  File "E:\Data Processing Evaluation Tool\mysite\QCtool\Item\PMNs.py", line 45, in __init__
    self.LOCATE,
TypeError: __init__() missing 1 required positional argument: 'LOCATE'
[2020-03-31 15:53:21,787] [ERROR] "POST / HTTP/1.1" 500 83502
[2020-03-31 15:53:37,780] [ERROR] Internal Server Error: /
Traceback (most recent call last):
  File "C:\Users\lihua\AppData\Local\Programs\Python\Python37\lib\site-packages\django\core\handlers\exception.py", line 34, in inner
    response = get_response(request)
  File "C:\Users\lihua\AppData\Local\Programs\Python\Python37\lib\site-packages\django\core\handlers\base.py", line 115, in _get_response
    response = self.process_exception_by_middleware(e, request)
  File "C:\Users\lihua\AppData\Local\Programs\Python\Python37\lib\site-packages\django\core\handlers\base.py", line 113, in _get_response
    response = wrapped_callback(request, *callback_args, **callback_kwargs)
  File "E:\Data Processing Evaluation Tool\mysite\QCtool\views.py", line 29, in file_upload
    raise e
  File "E:\Data Processing Evaluation Tool\mysite\QCtool\views.py", line 27, in file_upload
    content = handle_uploaded_file(file, item, num, types)
  File "E:\Data Processing Evaluation Tool\mysite\QCtool\Item\handle.py", line 23, in handle_uploaded_file
    return vd.output()
  File "E:\Data Processing Evaluation Tool\mysite\QCtool\Item\VD.py", line 525, in output
    dic = self.get_dic_data()
  File "E:\Data Processing Evaluation Tool\mysite\QCtool\Item\VD.py", line 295, in get_dic_data
    dic = self.AB_data_format_docx()
  File "E:\Data Processing Evaluation Tool\mysite\QCtool\Item\VD.py", line 258, in AB_data_format_docx
    dic[self.D2].append(read_table_data(D2table))
  File "E:\Data Processing Evaluation Tool\mysite\QCtool\Item\VD.py", line 236, in read_table_data
    cells = table._cells
AttributeError: 'list' object has no attribute '_cells'
[2020-03-31 15:53:37,871] [ERROR] "POST / HTTP/1.1" 500 107728
[2020-03-31 15:53:58,775] [INFO] E:\Data Processing Evaluation Tool\mysite\QCtool\Item\VD.py changed, reloading.
[2020-03-31 15:54:01,764] [INFO] Watching for file changes with StatReloader
[2020-03-31 15:54:05,527] [INFO] "GET / HTTP/1.1" 200 3290
[2020-03-31 15:54:13,971] [ERROR] Internal Server Error: /
Traceback (most recent call last):
  File "C:\Users\lihua\AppData\Local\Programs\Python\Python37\lib\site-packages\django\core\handlers\exception.py", line 34, in inner
    response = get_response(request)
  File "C:\Users\lihua\AppData\Local\Programs\Python\Python37\lib\site-packages\django\core\handlers\base.py", line 115, in _get_response
    response = self.process_exception_by_middleware(e, request)
  File "C:\Users\lihua\AppData\Local\Programs\Python\Python37\lib\site-packages\django\core\handlers\base.py", line 113, in _get_response
    response = wrapped_callback(request, *callback_args, **callback_kwargs)
  File "E:\Data Processing Evaluation Tool\mysite\QCtool\views.py", line 29, in file_upload
    raise e
  File "E:\Data Processing Evaluation Tool\mysite\QCtool\views.py", line 27, in file_upload
    content = handle_uploaded_file(file, item, num, types)
  File "E:\Data Processing Evaluation Tool\mysite\QCtool\Item\handle.py", line 23, in handle_uploaded_file
    return vd.output()
  File "E:\Data Processing Evaluation Tool\mysite\QCtool\Item\VD.py", line 525, in output
    dic = self.get_dic_data()
  File "E:\Data Processing Evaluation Tool\mysite\QCtool\Item\VD.py", line 295, in get_dic_data
    dic = self.AB_data_format_docx()
  File "E:\Data Processing Evaluation Tool\mysite\QCtool\Item\VD.py", line 258, in AB_data_format_docx
    dic[self.D2].append(read_table_data(D2table))
  File "E:\Data Processing Evaluation Tool\mysite\QCtool\Item\VD.py", line 238, in read_table_data
    COLUMNS = len(table.colums)
AttributeError: 'Table' object has no attribute 'colums'
[2020-03-31 15:54:14,032] [ERROR] "POST / HTTP/1.1" 500 98958
[2020-03-31 15:54:22,514] [INFO] E:\Data Processing Evaluation Tool\mysite\QCtool\Item\VD.py changed, reloading.
[2020-03-31 15:54:23,415] [INFO] Watching for file changes with StatReloader
[2020-03-31 15:54:24,544] [ERROR] Internal Server Error: /
Traceback (most recent call last):
  File "C:\Users\lihua\AppData\Local\Programs\Python\Python37\lib\site-packages\django\core\handlers\exception.py", line 34, in inner
    response = get_response(request)
  File "C:\Users\lihua\AppData\Local\Programs\Python\Python37\lib\site-packages\django\core\handlers\base.py", line 115, in _get_response
    response = self.process_exception_by_middleware(e, request)
  File "C:\Users\lihua\AppData\Local\Programs\Python\Python37\lib\site-packages\django\core\handlers\base.py", line 113, in _get_response
    response = wrapped_callback(request, *callback_args, **callback_kwargs)
  File "E:\Data Processing Evaluation Tool\mysite\QCtool\views.py", line 29, in file_upload
    raise e
  File "E:\Data Processing Evaluation Tool\mysite\QCtool\views.py", line 27, in file_upload
    content = handle_uploaded_file(file, item, num, types)
  File "E:\Data Processing Evaluation Tool\mysite\QCtool\Item\handle.py", line 23, in handle_uploaded_file
    return vd.output()
  File "E:\Data Processing Evaluation Tool\mysite\QCtool\Item\VD.py", line 525, in output
    dic = self.get_dic_data()
  File "E:\Data Processing Evaluation Tool\mysite\QCtool\Item\VD.py", line 295, in get_dic_data
    dic = self.AB_data_format_docx()
  File "E:\Data Processing Evaluation Tool\mysite\QCtool\Item\VD.py", line 260, in AB_data_format_docx
    raise
RuntimeError: No active exception to reraise
[2020-03-31 15:54:24,626] [ERROR] "POST / HTTP/1.1" 500 95803
[2020-03-31 15:55:01,724] [INFO] E:\Data Processing Evaluation Tool\mysite\QCtool\Item\VD.py changed, reloading.
[2020-03-31 15:55:02,821] [INFO] Watching for file changes with StatReloader
[2020-03-31 15:55:35,321] [INFO] E:\Data Processing Evaluation Tool\mysite\QCtool\Item\PMNs.py changed, reloading.
[2020-03-31 15:55:36,324] [INFO] Watching for file changes with StatReloader
[2020-03-31 15:55:40,019] [INFO] E:\Data Processing Evaluation Tool\mysite\QCtool\Item\UMNs.py changed, reloading.
[2020-03-31 15:55:40,860] [INFO] Watching for file changes with StatReloader
[2020-03-31 15:55:47,031] [INFO] E:\Data Processing Evaluation Tool\mysite\QCtool\Item\UMNs.py changed, reloading.
[2020-03-31 15:55:47,928] [INFO] Watching for file changes with StatReloader
[2020-03-31 15:55:58,326] [INFO] E:\Data Processing Evaluation Tool\mysite\QCtool\Item\UAld.py changed, reloading.
[2020-03-31 15:55:59,259] [INFO] Watching for file changes with StatReloader
[2020-03-31 15:56:05,622] [INFO] E:\Data Processing Evaluation Tool\mysite\QCtool\Item\Ald.py changed, reloading.
[2020-03-31 15:56:06,473] [INFO] Watching for file changes with StatReloader
[2020-03-31 15:56:12,683] [INFO] E:\Data Processing Evaluation Tool\mysite\QCtool\Item\Ald.py changed, reloading.
[2020-03-31 15:56:13,581] [INFO] Watching for file changes with StatReloader
[2020-03-31 15:56:17,357] [INFO] E:\Data Processing Evaluation Tool\mysite\QCtool\Item\PMNs.py changed, reloading.
[2020-03-31 15:56:18,215] [INFO] Watching for file changes with StatReloader
[2020-03-31 15:56:21,555] [ERROR] Internal Server Error: /
Traceback (most recent call last):
  File "C:\Users\lihua\AppData\Local\Programs\Python\Python37\lib\site-packages\django\core\handlers\exception.py", line 34, in inner
    response = get_response(request)
  File "C:\Users\lihua\AppData\Local\Programs\Python\Python37\lib\site-packages\django\core\handlers\base.py", line 115, in _get_response
    response = self.process_exception_by_middleware(e, request)
  File "C:\Users\lihua\AppData\Local\Programs\Python\Python37\lib\site-packages\django\core\handlers\base.py", line 113, in _get_response
    response = wrapped_callback(request, *callback_args, **callback_kwargs)
  File "E:\Data Processing Evaluation Tool\mysite\QCtool\views.py", line 29, in file_upload
    raise e
  File "E:\Data Processing Evaluation Tool\mysite\QCtool\views.py", line 27, in file_upload
    content = handle_uploaded_file(file, item, num, types)
  File "E:\Data Processing Evaluation Tool\mysite\QCtool\Item\handle.py", line 23, in handle_uploaded_file
    return vd.output()
  File "E:\Data Processing Evaluation Tool\mysite\QCtool\Item\VD.py", line 544, in output
    data = self.get_totalDmean(dic)
  File "E:\Data Processing Evaluation Tool\mysite\QCtool\Item\VD.py", line 395, in get_totalDmean
    samplename = data['D2'][0].index(self.NAME)
ValueError: 'Sample Name' is not in list
[2020-03-31 15:56:21,677] [ERROR] "POST / HTTP/1.1" 500 101228
[2020-03-31 15:57:27,013] [ERROR] Internal Server Error: /
Traceback (most recent call last):
  File "C:\Users\lihua\AppData\Local\Programs\Python\Python37\lib\site-packages\django\core\handlers\exception.py", line 34, in inner
    response = get_response(request)
  File "C:\Users\lihua\AppData\Local\Programs\Python\Python37\lib\site-packages\django\core\handlers\base.py", line 115, in _get_response
    response = self.process_exception_by_middleware(e, request)
  File "C:\Users\lihua\AppData\Local\Programs\Python\Python37\lib\site-packages\django\core\handlers\base.py", line 113, in _get_response
    response = wrapped_callback(request, *callback_args, **callback_kwargs)
  File "E:\Data Processing Evaluation Tool\mysite\QCtool\views.py", line 29, in file_upload
    raise e
  File "E:\Data Processing Evaluation Tool\mysite\QCtool\views.py", line 27, in file_upload
    content = handle_uploaded_file(file, item, num, types)
  File "E:\Data Processing Evaluation Tool\mysite\QCtool\Item\handle.py", line 23, in handle_uploaded_file
    return vd.output()
  File "E:\Data Processing Evaluation Tool\mysite\QCtool\Item\VD.py", line 544, in output
    data = self.get_totalDmean(dic)
  File "E:\Data Processing Evaluation Tool\mysite\QCtool\Item\VD.py", line 395, in get_totalDmean
    samplename = data['D2'][0].index(self.NAME)
ValueError: 'Sample Name' is not in list
[2020-03-31 15:57:27,137] [ERROR] "POST / HTTP/1.1" 500 101228
[2020-03-31 15:57:49,356] [INFO] E:\Data Processing Evaluation Tool\mysite\QCtool\Item\VD.py changed, reloading.
[2020-03-31 15:57:50,287] [INFO] Watching for file changes with StatReloader
[2020-03-31 15:57:52,606] [INFO] 提交数据:YZ02-20200330-S1-质量评估工具.docx
[2020-03-31 15:57:52,663] [INFO] "POST / HTTP/1.1" 200 34978
[2020-03-31 15:57:55,947] [INFO] "GET / HTTP/1.1" 200 3290
[2020-03-31 15:58:05,049] [INFO] 提交数据:YZ06-20200307-质量评估工具.csv
[2020-03-31 15:58:05,084] [INFO] "POST / HTTP/1.1" 200 33560
[2020-03-31 15:58:07,125] [INFO] "GET / HTTP/1.1" 200 3290
[2020-03-31 15:58:18,431] [INFO] 提交数据:YZ18-20200330-S1-质量评估工具.docx
[2020-03-31 15:58:18,449] [INFO] "POST / HTTP/1.1" 200 26079
[2020-03-31 15:59:10,966] [INFO] "GET / HTTP/1.1" 200 3290
[2020-03-31 15:59:44,925] [INFO] 提交数据:20191208.txt
[2020-03-31 15:59:44,952] [INFO] "POST / HTTP/1.1" 200 13040
[2020-03-31 15:59:49,684] [INFO] "GET / HTTP/1.1" 200 3290
[2020-03-31 15:59:59,411] [INFO] 提交数据:Ald-20200118.txt
[2020-03-31 15:59:59,461] [INFO] "POST / HTTP/1.1" 200 7696
[2020-03-31 16:00:01,068] [INFO] "GET / HTTP/1.1" 200 3290
[2020-03-31 16:00:13,214] [ERROR] Internal Server Error: /
Traceback (most recent call last):
  File "C:\Users\lihua\AppData\Local\Programs\Python\Python37\lib\site-packages\django\core\handlers\exception.py", line 34, in inner
    response = get_response(request)
  File "C:\Users\lihua\AppData\Local\Programs\Python\Python37\lib\site-packages\django\core\handlers\base.py", line 115, in _get_response
    response = self.process_exception_by_middleware(e, request)
  File "C:\Users\lihua\AppData\Local\Programs\Python\Python37\lib\site-packages\django\core\handlers\base.py", line 113, in _get_response
    response = wrapped_callback(request, *callback_args, **callback_kwargs)
  File "E:\Data Processing Evaluation Tool\mysite\QCtool\views.py", line 29, in file_upload
    raise e
  File "E:\Data Processing Evaluation Tool\mysite\QCtool\views.py", line 27, in file_upload
    content = handle_uploaded_file(file, item, num, types)
  File "E:\Data Processing Evaluation Tool\mysite\QCtool\Item\handle.py", line 19, in handle_uploaded_file
    umns = UMNs(f=f, instrument_num=instrument_num, instrument_type=instrument_type)
  File "E:\Data Processing Evaluation Tool\mysite\QCtool\Item\UMNs.py", line 35, in __init__
    super().__init__(self.NAME,
AttributeError: 'UMNs' object has no attribute 'NAME'
[2020-03-31 16:00:13,251] [ERROR] "POST / HTTP/1.1" 500 83176
[2020-03-31 16:00:30,248] [INFO] 提交数据:20200120.xml
[2020-03-31 16:00:30,266] [INFO] "POST / HTTP/1.1" 200 12930
[2020-03-31 16:00:32,830] [INFO] "GET / HTTP/1.1" 200 3290
[2020-03-31 16:04:01,561] [INFO] E:\Data Processing Evaluation Tool\mysite\QCtool\Item\VD.py changed, reloading.
[2020-03-31 16:04:02,459] [INFO] Watching for file changes with StatReloader
[2020-03-31 17:25:52,928] [INFO] Watching for file changes with StatReloader
[2020-03-31 17:41:25,764] [INFO] Watching for file changes with StatReloader
[2020-03-31 17:41:29,845] [INFO] "GET / HTTP/1.1" 200 3290
[2020-03-31 17:41:30,523] [WARNING] Not Found: /favicon.ico
[2020-03-31 17:41:30,524] [WARNING] "GET /favicon.ico HTTP/1.1" 404 2323
